Workbook

Sheet MAIN DATA 
A1: Sector | B1: Year | C1: Month | D1: Cereals and products | E1: Meat and fish | F1: Egg | G1: Milk and products | H1: Oils and fats | I1: Fruits | J1: Vegetables | K1: Pulses and products | L1: Sugar and Confectionery | M1: Spices | N1: Non-alcoholic beverages | O1: Prepared meals, snacks, sweets etc. | P1: Food and beverages | Q1: Pan, tobacco and intoxicants | R1: Clothing | S1: Footwear | T1: Clothing and footwear | U1: Housing | V1: Fuel and light | W1: Household goods and services | X1: Health | Y1: Transport and communication | Z1: Recreation and amusement | AA1: Education | AB1: Personal care and effects | AC1: Miscellaneous | AD1: General index | AG1: FOOD & NON-ALCHOLIC BEVERAGES | AH1: ALCOHOL,TOBACCO & INTOXICANTS | AI1: CLOTHING AND FOOTWEAR | AJ1: HOUSING,FUEL AND UTILITIES | AK1: HEALTHCARE AND EDUCATION | AL1: TRANSPORT & COMMUNICATION | AM1: RECREATION AND CULTURE | AN1: MISCELLANEOUS
A2: Rural | B2: 2013 | C2: January | D2: 107.5 | E2: 106.3 | F2: 108.1 | G2: 104.9 | H2: 106.1 | I2: 103.9 | J2: 101.9 | K2: 106.1 | L2: 106.8 | M2: 103.1 | N2: 104.8 | O2: 106.7 | P2: 105.5 | Q2: 105.1 | R2: 106.5 | S2: 105.8 | T2: 106.4 | U2: NA | V2: 105.5 | W2: 104.8 | X2: 104 | Y2: 103.3 | Z2: 103.4 | AA2: 103.8 | AB2: 104.7 | AC2: 104 | AD2: 105.1 | AG2: =SUM(D2:P2) -> 1371.7 | AH2: =SUM(Q2) -> 105.1 | AI2: =SUM(R2:T2) -> 318.7 | AJ2: =SUM(U2:W2) -> 210.3 | AK2: =SUM(X2,AA2,AB2) -> 312.5 | AL2: =SUM(Y2) -> 103.3 | AM2: =SUM(Z2) -> 103.4 | AN2: =SUM(AC2) -> 104
A3: Urban | B3: 2013 | C3: January | D3: 110.5 | E3: 109.1 | F3: 113 | G3: 103.6 | H3: 103.4 | I3: 102.3 | J3: 102.9 | K3: 105.8 | L3: 105.1 | M3: 101.8 | N3: 105.1 | O3: 107.9 | P3: 105.9 | Q3: 105.2 | R3: 105.9 | S3: 105 | T3: 105.8 | U3: 100.3 | V3: 105.4 | W3: 104.8 | X3: 104.1 | Y3: 103.2 | Z3: 102.9 | AA3: 103.5 | AB3: 104.3 | AC3: 103.7 | AD3: 104 | AG3: =SUM(D3:P3) -> 1376.4 | AH3: =SUM(Q3) -> 105.2 | AI3: =SUM(R3:T3) -> 316.7 | AJ3: =SUM(U3:W3) -> 310.5 | AK3: =SUM(X3,AA3,AB3) -> 311.9 | AL3: =SUM(Y3) -> 103.2 | AM3: =SUM(Z3) -> 102.9 | AN3: =SUM(AC3) -> 103.7
A4: Rural+Urban | B4: 2013 | C4: January | D4: 108.4 | E4: 107.3 | F4: 110 | G4: 104.4 | H4: 105.1 | I4: 103.2 | J4: 102.2 | K4: 106 | L4: 106.2 | M4: 102.7 | N4: 104.9 | O4: 107.3 | P4: 105.6 | Q4: 105.1 | R4: 106.3 | S4: 105.5 | T4: 106.2 | U4: 100.3 | V4: 105.5 | W4: 104.8 | X4: 104 | Y4: 103.2 | Z4: 103.1 | AA4: 103.6 | AB4: 104.5 | AC4: 103.9 | AD4: 104.6 | AG4: =SUM(D4:P4) -> 1373.3 | AH4: =SUM(Q4) -> 105.1 | AI4: =SUM(R4:T4) -> 318 | AJ4: =SUM(U4:W4) -> 310.6 | AK4: =SUM(X4,AA4,AB4) -> 312.1 | AL4: =SUM(Y4) -> 103.2 | AM4: =SUM(Z4) -> 103.1 | AN4: =SUM(AC4) -> 103.9
A5: Rural | B5: 2013 | C5: February | D5: 109.2 | E5: 108.7 | F5: 110.2 | G5: 105.4 | H5: 106.7 | I5: 104 | J5: 102.4 | K5: 105.9 | L5: 105.7 | M5: 103.1 | N5: 105.1 | O5: 107.7 | P5: 106.3 | Q5: 105.6 | R5: 107.1 | S5: 106.3 | T5: 107 | U5: NA | V5: 106.2 | W5: 105.2 | X5: 104.4 | Y5: 103.9 | Z5: 104 | AA5: 104.1 | AB5: 104.6 | AC5: 104.4 | AD5: 105.8 | AG5: =SUM(D5:P5) -> 1380.4 | AH5: =SUM(Q5) -> 105.6 | AI5: =SUM(R5:T5) -> 320.4 | AJ5: =SUM(U5:W5) -> 211.4 | AK5: =SUM(X5,AA5,AB5) -> 313.1 | AL5: =SUM(Y5) -> 103.9 | AM5: =SUM(Z5) -> 104 | AN5: =SUM(AC5) -> 104.4
A6: Urban | B6: 2013 | C6: February | D6: 112.9 | E6: 112.9 | F6: 116.9 | G6: 104 | H6: 103.5 | I6: 103.1 | J6: 104.9 | K6: 104.1 | L6: 103.8 | M6: 102.3 | N6: 106 | O6: 109 | P6: 107.2 | Q6: 106 | R6: 106.6 | S6: 105.5 | T6: 106.4 | U6: 100.4 | V6: 105.7 | W6: 105.2 | X6: 104.7 | Y6: 104.4 | Z6: 103.3 | AA6: 103.7 | AB6: 104.3 | AC6: 104.3 | AD6: 104.7 | AG6: =SUM(D6:P6) -> 1390.6 | AH6: =SUM(Q6) -> 106 | AI6: =SUM(R6:T6) -> 318.5 | AJ6: =SUM(U6:W6) -> 311.3 | AK6: =SUM(X6,AA6,AB6) -> 312.7 | AL6: =SUM(Y6) -> 104.4 | AM6: =SUM(Z6) -> 103.3 | AN6: =SUM(AC6) -> 104.3
A7: Rural+Urban | B7: 2013 | C7: February | D7: 110.4 | E7: 110.2 | F7: 112.8 | G7: 104.9 | H7: 105.5 | I7: 103.6 | J7: 103.2 | K7: 105.3 | L7: 105.1 | M7: 102.8 | N7: 105.5 | O7: 108.3 | P7: 106.6 | Q7: 105.7 | R7: 106.9 | S7: 106 | T7: 106.8 | U7: 100.4 | V7: 106 | W7: 105.2 | X7: 104.5 | Y7: 104.2 | Z7: 103.6 | AA7: 103.9 | AB7: 104.5 | AC7: 104.4 | AD7: 105.3 | AG7: =SUM(D7:P7) -> 1384.2 | AH7: =SUM(Q7) -> 105.7 | AI7: =SUM(R7:T7) -> 319.7 | AJ7: =SUM(U7:W7) -> 311.6 | AK7: =SUM(X7,AA7,AB7) -> 312.9 | AL7: =SUM(Y7) -> 104.2 | AM7: =SUM(Z7) -> 103.6 | AN7: =SUM(AC7) -> 104.4
A8: Rural | B8: 2013 | C8: March | D8: 110.2 | E8: 108.8 | F8: 109.9 | G8: 105.6 | H8: 106.2 | I8: 105.7 | J8: 101.4 | K8: 105.7 | L8: 105 | M8: 103.3 | N8: 105.6 | O8: 108.2 | P8: 106.6 | Q8: 106.5 | R8: 107.6 | S8: 106.8 | T8: 107.5 | U8: NA | V8: 106.1 | W8: 105.6 | X8: 104.7 | Y8: 104.6 | Z8: 104 | AA8: 104.3 | AB8: 104.3 | AC8: 104.6 | AD8: 106 | AG8: =SUM(D8:P8) -> 1382.2 | AH8: =SUM(Q8) -> 106.5 | AI8: =SUM(R8:T8) -> 321.9 | AJ8: =SUM(U8:W8) -> 211.7 | AK8: =SUM(X8,AA8,AB8) -> 313.3 | AL8: =SUM(Y8) -> 104.6 | AM8: =SUM(Z8) -> 104 | AN8: =SUM(AC8) -> 104.6
A9: Urban | B9: 2013 | C9: March | D9: 113.9 | E9: 111.4 | F9: 113.2 | G9: 104.3 | H9: 102.7 | I9: 104.9 | J9: 103.8 | K9: 103.5 | L9: 102.6 | M9: 102.4 | N9: 107 | O9: 109.8 | P9: 107.3 | Q9: 106.8 | R9: 107.2 | S9: 106 | T9: 107 | U9: 100.4 | V9: 106 | W9: 105.7 | X9: 105.2 | Y9: 105.5 | Z9: 103.5 | AA9: 103.8 | AB9: 104.2 | AC9: 104.9 | AD9: 105 | AG9: =SUM(D9:P9) -> 1386.8 | AH9: =SUM(Q9) -> 106.8 | AI9: =SUM(R9:T9) -> 320.2 | AJ9: =SUM(U9:W9) -> 312.1 | AK9: =SUM(X9,AA9,AB9) -> 313.2 | AL9: =SUM(Y9) -> 105.5 | AM9: =SUM(Z9) -> 103.5 | AN9: =SUM(AC9) -> 104.9
A10: Rural+Urban | B10: 2013 | C10: March | D10: 111.4 | E10: 109.7 | F10: 111.2 | G10: 105.1 | H10: 104.9 | I10: 105.3 | J10: 102.2 | K10: 105 | L10: 104.2 | M10: 103 | N10: 106.2 | O10: 108.9 | P10: 106.9 | Q10: 106.6 | R10: 107.4 | S10: 106.5 | T10: 107.3 | U10: 100.4 | V10: 106.1 | W10: 105.6 | X10: 104.9 | Y10: 105.1 | Z10: 103.7 | AA10: 104 | AB10: 104.3 | AC10: 104.7 | AD10: 105.5 | AG10: =SUM(D10:P10) -> 1384 | AH10: =SUM(Q10) -> 106.6 | AI10: =SUM(R10:T10) -> 321.2 | AJ10: =SUM(U10:W10) -> 312.1 | AK10: =SUM(X10,AA10,AB10) -> 313.2 | AL10: =SUM(Y10) -> 105.1 | AM10: =SUM(Z10) -> 103.7 | AN10: =SUM(AC10) -> 104.7
A11: Rural | B11: 2013 | C11: April | D11: 110.2 | E11: 109.5 | F11: 106.9 | G11: 106.3 | H11: 105.7 | I11: 108.3 | J11: 103.4 | K11: 105.7 | L11: 104.2 | M11: 103.2 | N11: 106.5 | O11: 108.8 | P11: 107.1 | Q11: 107.1 | R11: 108.1 | S11: 107.4 | T11: 108 | U11: NA | V11: 106.5 | W11: 106.1 | X11: 105.1 | Y11: 104.4 | Z11: 104.5 | AA11: 104.8 | AB11: 102.7 | AC11: 104.6 | AD11: 106.4 | AG11: =SUM(D11:P11) -> 1385.8 | AH11: =SUM(Q11) -> 107.1 | AI11: =SUM(R11:T11) -> 323.5 | AJ11: =SUM(U11:W11) -> 212.6 | AK11: =SUM(X11,AA11,AB11) -> 312.6 | AL11: =SUM(Y11) -> 104.4 | AM11: =SUM(Z11) -> 104.5 | AN11: =SUM(AC11) -> 104.6
A12: Urban | B12: 2013 | C12: April | D12: 114.6 | E12: 113.4 | F12: 106 | G12: 104.7 | H12: 102.1 | I12: 109.5 | J12: 109.7 | K12: 104.6 | L12: 102 | M12: 103.5 | N12: 108.2 | O12: 110.6 | P12: 108.8 | Q12: 108.5 | R12: 107.9 | S12: 106.4 | T12: 107.7 | U12: 100.5 | V12: 106.4 | W12: 106.5 | X12: 105.7 | Y12: 105 | Z12: 104 | AA12: 105.2 | AB12: 103.2 | AC12: 105.1 | AD12: 105.7 | AG12: =SUM(D12:P12) -> 1397.7 | AH12: =SUM(Q12) -> 108.5 | AI12: =SUM(R12:T12) -> 322 | AJ12: =SUM(U12:W12) -> 313.4 | AK12: =SUM(X12,AA12,AB12) -> 314.1 | AL12: =SUM(Y12) -> 105 | AM12: =SUM(Z12) -> 104 | AN12: =SUM(AC12) -> 105.1
A13: Rural+Urban | B13: 2013 | C13: April | D13: 111.6 | E13: 110.9 | F13: 106.6 | G13: 105.7 | H13: 104.4 | I13: 108.9 | J13: 105.5 | K13: 105.3 | L13: 103.5 | M13: 103.3 | N13: 107.2 | O13: 109.6 | P13: 107.7 | Q13: 107.5 | R13: 108 | S13: 107 | T13: 107.9 | U13: 100.5 | V13: 106.5 | W13: 106.3 | X13: 105.3 | Y13: 104.7 | Z13: 104.2 | AA13: 105 | AB13: 102.9 | AC13: 104.8 | AD13: 106.1 | AG13: =SUM(D13:P13) -> 1390.2 | AH13: =SUM(Q13) -> 107.5 | AI13: =SUM(R13:T13) -> 322.9 | AJ13: =SUM(U13:W13) -> 313.3 | AK13: =SUM(X13,AA13,AB13) -> 313.2 | AL13: =SUM(Y13) -> 104.7 | AM13: =SUM(Z13) -> 104.2 | AN13: =SUM(AC13) -> 104.8
A14: Rural | B14: 2013 | C14: May | D14: 110.9 | E14: 109.8 | F14: 105.9 | G14: 107.5 | H14: 105.3 | I14: 108.1 | J14: 107.3 | K14: 106.1 | L14: 103.7 | M14: 104 | N14: 107.4 | O14: 109.9 | P14: 108.1 | Q14: 108.1 | R14: 108.8 | S14: 107.9 | T14: 108.6 | U14: NA | V14: 107.5 | W14: 106.8 | X14: 105.7 | Y14: 104.1 | Z14: 105 | AA14: 105.5 | AB14: 102.1 | AC14: 104.8 | AD14: 107.2 | AG14: =SUM(D14:P14) -> 1394 | AH14: =SUM(Q14) -> 108.1 | AI14: =SUM(R14:T14) -> 325.3 | AJ14: =SUM(U14:W14) -> 214.3 | AK14: =SUM(X14,AA14,AB14) -> 313.3 | AL14: =SUM(Y14) -> 104.1 | AM14: =SUM(Z14) -> 105 | AN14: =SUM(AC14) -> 104.8
A15: Urban | B15: 2013 | C15: May | D15: 115.4 | E15: 114.2 | F15: 102.7 | G15: 105.5 | H15: 101.5 | I15: 110.6 | J15: 123.7 | K15: 105.2 | L15: 101.9 | M15: 105 | N15: 109.1 | O15: 111.3 | P15: 111.1 | Q15: 109.8 | R15: 108.5 | S15: 106.7 | T15: 108.3 | U15: 100.5 | V15: 107.2 | W15: 107.1 | X15: 106.2 | Y15: 103.9 | Z15: 104.6 | AA15: 105.7 | AB15: 102.6 | AC15: 104.9 | AD15: 106.6 | AG15: =SUM(D15:P15) -> 1417.2 | AH15: =SUM(Q15) -> 109.8 | AI15: =SUM(R15:T15) -> 323.5 | AJ15: =SUM(U15:W15) -> 314.8 | AK15: =SUM(X15,AA15,AB15) -> 314.5 | AL15: =SUM(Y15) -> 103.9 | AM15: =SUM(Z15) -> 104.6 | AN15: =SUM(AC15) -> 104.9
A16: Rural+Urban | B16: 2013 | C16: May | D16: 112.3 | E16: 111.3 | F16: 104.7 | G16: 106.8 | H16: 103.9 | I16: 109.3 | J16: 112.9 | K16: 105.8 | L16: 103.1 | M16: 104.3 | N16: 108.1 | O16: 110.5 | P16: 109.2 | Q16: 108.6 | R16: 108.7 | S16: 107.4 | T16: 108.5 | U16: 100.5 | V16: 107.4 | W16: 106.9 | X16: 105.9 | Y16: 104 | Z16: 104.8 | AA16: 105.6 | AB16: 102.3 | AC16: 104.8 | AD16: 106.9 | AG16: =SUM(D16:P16) -> 1402.2 | AH16: =SUM(Q16) -> 108.6 | AI16: =SUM(R16:T16) -> 324.6 | AJ16: =SUM(U16:W16) -> 314.8 | AK16: =SUM(X16,AA16,AB16) -> 313.8 | AL16: =SUM(Y16) -> 104 | AM16: =SUM(Z16) -> 104.8 | AN16: =SUM(AC16) -> 104.8
A17: Rural | B17: 2013 | C17: June | D17: 112.3 | E17: 112.1 | F17: 108.1 | G17: 108.3 | H17: 105.9 | I17: 109.2 | J17: 118 | K17: 106.8 | L17: 104.1 | M17: 105.4 | N17: 108.2 | O17: 111 | P17: 110.6 | Q17: 109 | R17: 109.7 | S17: 108.8 | T17: 109.5 | U17: NA | V17: 108.5 | W17: 107.5 | X17: 106.3 | Y17: 105 | Z17: 105.6 | AA17: 106.5 | AB17: 102.5 | AC17: 105.5 | AD17: 108.9 | AG17: =SUM(D17:P17) -> 1420 | AH17: =SUM(Q17) -> 109 | AI17: =SUM(R17:T17) -> 328 | AJ17: =SUM(U17:W17) -> 216 | AK17: =SUM(X17,AA17,AB17) -> 315.3 | AL17: =SUM(Y17) -> 105 | AM17: =SUM(Z17) -> 105.6 | AN17: =SUM(AC17) -> 105.5
A18: Urban | B18: 2013 | C18: June | D18: 117 | E18: 120.1 | F18: 112.5 | G18: 107.3 | H18: 101.3 | I18: 112.4 | J18: 143.6 | K18: 105.4 | L18: 101.4 | M18: 106.4 | N18: 110 | O18: 112.2 | P18: 115 | Q18: 110.9 | R18: 109.2 | S18: 107.2 | T18: 108.9 | U18: 106.6 | V18: 108 | W18: 107.7 | X18: 106.5 | Y18: 105.2 | Z18: 105.2 | AA18: 108.1 | AB18: 103.3 | AC18: 106.1 | AD18: 109.7 | AG18: =SUM(D18:P18) -> 1464.6 | AH18: =SUM(Q18) -> 110.9 | AI18: =SUM(R18:T18) -> 325.3 | AJ18: =SUM(U18:W18) -> 322.3 | AK18: =SUM(X18,AA18,AB18) -> 317.9 | AL18: =SUM(Y18) -> 105.2 | AM18: =SUM(Z18) -> 105.2 | AN18: =SUM(AC18) -> 106.1
A19: Rural+Urban | B19: 2013 | C19: June | D19: 113.8 | E19: 114.9 | F19: 109.8 | G19: 107.9 | H19: 104.2 | I19: 110.7 | J19: 126.7 | K19: 106.3 | L19: 103.2 | M19: 105.7 | N19: 109 | O19: 111.6 | P19: 112.2 | Q19: 109.5 | R19: 109.5 | S19: 108.1 | T19: 109.3 | U19: 106.6 | V19: 108.3 | W19: 107.6 | X19: 106.4 | Y19: 105.1 | Z19: 105.4 | AA19: 107.4 | AB19: 102.8 | AC19: 105.8 | AD19: 109.3 | AG19: =SUM(D19:P19) -> 1436 | AH19: =SUM(Q19) -> 109.5 | AI19: =SUM(R19:T19) -> 326.9 | AJ19: =SUM(U19:W19) -> 322.5 | AK19: =SUM(X19,AA19,AB19) -> 316.6 | AL19: =SUM(Y19) -> 105.1 | AM19: =SUM(Z19) -> 105.4 | AN19: =SUM(AC19) -> 105.8
A20: Rural | B20: 2013 | C20: July | D20: 113.4 | E20: 114.9 | F20: 110.5 | G20: 109.3 | H20: 106.2 | I20: 110.3 | J20: 129.2 | K20: 107.1 | L20: 104.3 | M20: 106.4 | N20: 109.1 | O20: 112.1 | P20: 113.1 | Q20: 109.8 | R20: 110.5 | S20: 109.5 | T20: 110.3 | U20: NA | V20: 109.5 | W20: 108.3 | X20: 106.9 | Y20: 106.8 | Z20: 106.4 | AA20: 107.8 | AB20: 102.5 | AC20: 106.5 | AD20: 110.7 | AG20: =SUM(D20:P20) -> 1445.9 | AH20: =SUM(Q20) -> 109.8 | AI20: =SUM(R20:T20) -> 330.3 | AJ20: =SUM(U20:W20) -> 217.8 | AK20: =SUM(X20,AA20,AB20) -> 317.2 | AL20: =SUM(Y20) -> 106.8 | AM20: =SUM(Z20) -> 106.4 | AN20: =SUM(AC20) -> 106.5
A21: Urban | B21: 2013 | C21: July | D21: 117.8 | E21: 119.2 | F21: 114 | G21: 108.3 | H21: 101.1 | I21: 113.2 | J21: 160.9 | K21: 105.1 | L21: 101.3 | M21: 107.5 | N21: 110.4 | O21: 113.1 | P21: 117.5 | Q21: 111.7 | R21: 109.8 | S21: 107.8 | T21: 109.5 | U21: 107.7 | V21: 108.6 | W21: 108.1 | X21: 107.1 | Y21: 107.3 | Z21: 105.9 | AA21: 110.1 | AB21: 103.2 | AC21: 107.3 | AD21: 111.4 | AG21: =SUM(D21:P21) -> 1489.4 | AH21: =SUM(Q21) -> 111.7 | AI21: =SUM(R21:T21) -> 327.1 | AJ21: =SUM(U21:W21) -> 324.4 | AK21: =SUM(X21,AA21,AB21) -> 320.4 | AL21: =SUM(Y21) -> 107.3 | AM21: =SUM(Z21) -> 105.9 | AN21: =SUM(AC21) -> 107.3
A22: Rural+Urban | B22: 2013 | C22: July | D22: 114.8 | E22: 116.4 | F22: 111.9 | G22: 108.9 | H22: 104.3 | I22: 111.7 | J22: 140 | K22: 106.4 | L22: 103.3 | M22: 106.8 | N22: 109.6 | O22: 112.6 | P22: 114.7 | Q22: 110.3 | R22: 110.2 | S22: 108.8 | T22: 110 | U22: 107.7 | V22: 109.2 | W22: 108.2 | X22: 107 | Y22: 107.1 | Z22: 106.1 | AA22: 109.1 | AB22: 102.8 | AC22: 106.9 | AD22: 111 | AG22: =SUM(D22:P22) -> 1461.4 | AH22: =SUM(Q22) -> 110.3 | AI22: =SUM(R22:T22) -> 329 | AJ22: =SUM(U22:W22) -> 325.1 | AK22: =SUM(X22,AA22,AB22) -> 318.9 | AL22: =SUM(Y22) -> 107.1 | AM22: =SUM(Z22) -> 106.1 | AN22: =SUM(AC22) -> 106.9
A23: Rural | B23: 2013 | C23: August | D23: 114.3 | E23: 115.4 | F23: 111.1 | G23: 110 | H23: 106.4 | I23: 110.8 | J23: 138.9 | K23: 107.4 | L23: 104.1 | M23: 106.9 | N23: 109.7 | O23: 112.6 | P23: 114.9 | Q23: 110.7 | R23: 111.3 | S23: 110.2 | T23: 111.1 | U23: NA | V23: 109.9 | W23: 108.7 | X23: 107.5 | Y23: 107.8 | Z23: 106.8 | AA23: 108.7 | AB23: 105 | AC23: 107.5 | AD23: 112.1 | AG23: =SUM(D23:P23) -> 1462.5 | AH23: =SUM(Q23) -> 110.7 | AI23: =SUM(R23:T23) -> 332.6 | AJ23: =SUM(U23:W23) -> 218.6 | AK23: =SUM(X23,AA23,AB23) -> 321.2 | AL23: =SUM(Y23) -> 107.8 | AM23: =SUM(Z23) -> 106.8 | AN23: =SUM(AC23) -> 107.5
A24: Urban | B24: 2013 | C24: August | D24: 118.3 | E24: 120.4 | F24: 112.7 | G24: 108.9 | H24: 101.1 | I24: 108.7 | J24: 177 | K24: 104.7 | L24: 101 | M24: 108.5 | N24: 110.9 | O24: 114.3 | P24: 119.6 | Q24: 112.4 | R24: 110.6 | S24: 108.3 | T24: 110.2 | U24: 108.9 | V24: 109.3 | W24: 108.7 | X24: 107.6 | Y24: 108.1 | Z24: 106.5 | AA24: 110.8 | AB24: 106 | AC24: 108.3 | AD24: 112.7 | AG24: =SUM(D24:P24) -> 1506.1 | AH24: =SUM(Q24) -> 112.4 | AI24: =SUM(R24:T24) -> 329.1 | AJ24: =SUM(U24:W24) -> 326.9 | AK24: =SUM(X24,AA24,AB24) -> 324.4 | AL24: =SUM(Y24) -> 108.1 | AM24: =SUM(Z24) -> 106.5 | AN24: =SUM(AC24) -> 108.3
A25: Rural+Urban | B25: 2013 | C25: August | D25: 115.6 | E25: 117.2 | F25: 111.7 | G25: 109.6 | H25: 104.5 | I25: 109.8 | J25: 151.8 | K25: 106.5 | L25: 103.1 | M25: 107.4 | N25: 110.2 | O25: 113.4 | P25: 116.6 | Q25: 111.2 | R25: 111 | S25: 109.4 | T25: 110.7 | U25: 108.9 | V25: 109.7 | W25: 108.7 | X25: 107.5 | Y25: 108 | Z25: 106.6 | AA25: 109.9 | AB25: 105.4 | AC25: 107.9 | AD25: 112.4 | AG25: =SUM(D25:P25) -> 1477.4 | AH25: =SUM(Q25) -> 111.2 | AI25: =SUM(R25:T25) -> 331.1 | AJ25: =SUM(U25:W25) -> 327.3 | AK25: =SUM(X25,AA25,AB25) -> 322.8 | AL25: =SUM(Y25) -> 108 | AM25: =SUM(Z25) -> 106.6 | AN25: =SUM(AC25) -> 107.9
A26: Rural | B26: 2013 | C26: September | D26: 115.4 | E26: 115.7 | F26: 111.7 | G26: 111 | H26: 107.4 | I26: 110.9 | J26: 154 | K26: 108.1 | L26: 104.2 | M26: 107.9 | N26: 110.4 | O26: 114 | P26: 117.8 | Q26: 111.7 | R26: 112.7 | S26: 111.4 | T26: 112.5 | U26: NA | V26: 111.1 | W26: 109.6 | X26: 108.3 | Y26: 109.3 | Z26: 107.7 | AA26: 109.8 | AB26: 106.7 | AC26: 108.7 | AD26: 114.2 | AG26: =SUM(D26:P26) -> 1488.5 | AH26: =SUM(Q26) -> 111.7 | AI26: =SUM(R26:T26) -> 336.6 | AJ26: =SUM(U26:W26) -> 220.7 | AK26: =SUM(X26,AA26,AB26) -> 324.8 | AL26: =SUM(Y26) -> 109.3 | AM26: =SUM(Z26) -> 107.7 | AN26: =SUM(AC26) -> 108.7
A27: Urban | B27: 2013 | C27: September | D27: 118.6 | E27: 119.1 | F27: 113.2 | G27: 109.6 | H27: 101.7 | I27: 103.2 | J27: 174.3 | K27: 105.1 | L27: 100.8 | M27: 109.1 | N27: 111.1 | O27: 115.4 | P27: 119.2 | Q27: 112.9 | R27: 111.4 | S27: 109 | T27: 111.1 | U27: 109.7 | V27: 109.5 | W27: 109.6 | X27: 107.9 | Y27: 110.4 | Z27: 107.4 | AA27: 111.2 | AB27: 106.9 | AC27: 109.4 | AD27: 113.2 | AG27: =SUM(D27:P27) -> 1500.4 | AH27: =SUM(Q27) -> 112.9 | AI27: =SUM(R27:T27) -> 331.5 | AJ27: =SUM(U27:W27) -> 328.8 | AK27: =SUM(X27,AA27,AB27) -> 326 | AL27: =SUM(Y27) -> 110.4 | AM27: =SUM(Z27) -> 107.4 | AN27: =SUM(AC27) -> 109.4
A28: Rural+Urban | B28: 2013 | C28: September | D28: 116.4 | E28: 116.9 | F28: 112.3 | G28: 110.5 | H28: 105.3 | I28: 107.3 | J28: 160.9 | K28: 107.1 | L28: 103.1 | M28: 108.3 | N28: 110.7 | O28: 114.6 | P28: 118.3 | Q28: 112 | R28: 112.2 | S28: 110.4 | T28: 111.9 | U28: 109.7 | V28: 110.5 | W28: 109.6 | X28: 108.1 | Y28: 109.9 | Z28: 107.5 | AA28: 110.6 | AB28: 106.8 | AC28: 109 | AD28: 113.7 | AG28: =SUM(D28:P28) -> 1491.7 | AH28: =SUM(Q28) -> 112 | AI28: =SUM(R28:T28) -> 334.5 | AJ28: =SUM(U28:W28) -> 329.8 | AK28: =SUM(X28,AA28,AB28) -> 325.5 | AL28: =SUM(Y28) -> 109.9 | AM28: =SUM(Z28) -> 107.5 | AN28: =SUM(AC28) -> 109
A29: Rural | B29: 2013 | C29: October | D29: 116.3 | E29: 115.4 | F29: 112.6 | G29: 111.7 | H29: 107.7 | I29: 113.2 | J29: 164.9 | K29: 108.3 | L29: 103.9 | M29: 108.2 | N29: 111.1 | O29: 114.9 | P29: 119.8 | Q29: 112.2 | R29: 113.6 | S29: 112.3 | T29: 113.4 | U29: NA | V29: 111.6 | W29: 110.4 | X29: 108.9 | Y29: 109.3 | Z29: 108.3 | AA29: 110.2 | AB29: 107.5 | AC29: 109.1 | AD29: 115.5 | AG29: =SUM(D29:P29) -> 1508 | AH29: =SUM(Q29) -> 112.2 | AI29: =SUM(R29:T29) -> 339.3 | AJ29: =SUM(U29:W29) -> 222 | AK29: =SUM(X29,AA29,AB29) -> 326.6 | AL29: =SUM(Y29) -> 109.3 | AM29: =SUM(Z29) -> 108.3 | AN29: =SUM(AC29) -> 109.1
A30: Urban | B30: 2013 | C30: October | D30: 118.9 | E30: 118.1 | F30: 114.5 | G30: 110.4 | H30: 102.3 | I30: 106.2 | J30: 183.5 | K30: 105.3 | L30: 100.2 | M30: 109.6 | N30: 111.4 | O30: 116 | P30: 120.8 | Q30: 113.5 | R30: 112.5 | S30: 109.7 | T30: 112 | U30: 110.5 | V30: 109.7 | W30: 110.2 | X30: 108.2 | Y30: 109.7 | Z30: 108 | AA30: 111.3 | AB30: 107.3 | AC30: 109.4 | AD30: 114 | AG30: =SUM(D30:P30) -> 1517.2 | AH30: =SUM(Q30) -> 113.5 | AI30: =SUM(R30:T30) -> 334.2 | AJ30: =SUM(U30:W30) -> 330.4 | AK30: =SUM(X30,AA30,AB30) -> 326.8 | AL30: =SUM(Y30) -> 109.7 | AM30: =SUM(Z30) -> 108 | AN30: =SUM(AC30) -> 109.4
A31: Rural+Urban | B31: 2013 | C31: October | D31: 117.1 | E31: 116.3 | F31: 113.3 | G31: 111.2 | H31: 105.7 | I31: 109.9 | J31: 171.2 | K31: 107.3 | L31: 102.7 | M31: 108.7 | N31: 111.2 | O31: 115.4 | P31: 120.2 | Q31: 112.5 | R31: 113.2 | S31: 111.2 | T31: 112.8 | U31: 110.5 | V31: 110.9 | W31: 110.3 | X31: 108.6 | Y31: 109.5 | Z31: 108.1 | AA31: 110.8 | AB31: 107.4 | AC31: 109.2 | AD31: 114.8 | AG31: =SUM(D31:P31) -> 1510.2 | AH31: =SUM(Q31) -> 112.5 | AI31: =SUM(R31:T31) -> 337.2 | AJ31: =SUM(U31:W31) -> 331.7 | AK31: =SUM(X31,AA31,AB31) -> 326.8 | AL31: =SUM(Y31) -> 109.5 | AM31: =SUM(Z31) -> 108.1 | AN31: =SUM(AC31) -> 109.2
A32: Rural | B32: 2013 | C32: November | D32: 117.3 | E32: 114.9 | F32: 116.2 | G32: 112.8 | H32: 108.9 | I32: 116.6 | J32: 178.1 | K32: 109.1 | L32: 103.6 | M32: 109 | N32: 111.8 | O32: 116 | P32: 122.5 | Q32: 112.8 | R32: 114.6 | S32: 113.1 | T32: 114.4 | U32: NA | V32: 112.6 | W32: 111.3 | X32: 109.7 | Y32: 109.6 | Z32: 108.7 | AA32: 111 | AB32: 108.2 | AC32: 109.8 | AD32: 117.4 | AG32: =SUM(D32:P32) -> 1536.8 | AH32: =SUM(Q32) -> 112.8 | AI32: =SUM(R32:T32) -> 342.1 | AJ32: =SUM(U32:W32) -> 223.9 | AK32: =SUM(X32,AA32,AB32) -> 328.9 | AL32: =SUM(Y32) -> 109.6 | AM32: =SUM(Z32) -> 108.7 | AN32: =SUM(AC32) -> 109.8
A33: Urban | B33: 2013 | C33: November | D33: 119.8 | E33: 116.3 | F33: 122.6 | G33: 112 | H33: 103.2 | I33: 110 | J33: 192.8 | K33: 106.3 | L33: 99.5 | M33: 110.3 | N33: 111.8 | O33: 117.1 | P33: 122.9 | Q33: 114.1 | R33: 113.5 | S33: 110.3 | T33: 113 | U33: 111.1 | V33: 110 | W33: 110.9 | X33: 108.6 | Y33: 109.5 | Z33: 108.5 | AA33: 111.3 | AB33: 107.9 | AC33: 109.6 | AD33: 115 | AG33: =SUM(D33:P33) -> 1544.6 | AH33: =SUM(Q33) -> 114.1 | AI33: =SUM(R33:T33) -> 336.8 | AJ33: =SUM(U33:W33) -> 332 | AK33: =SUM(X33,AA33,AB33) -> 327.8 | AL33: =SUM(Y33) -> 109.5 | AM33: =SUM(Z33) -> 108.5 | AN33: =SUM(AC33) -> 109.6
A34: Rural+Urban | B34: 2013 | C34: November | D34: 118.1 | E34: 115.4 | F34: 118.7 | G34: 112.5 | H34: 106.8 | I34: 113.5 | J34: 183.1 | K34: 108.2 | L34: 102.2 | M34: 109.4 | N34: 111.8 | O34: 116.5 | P34: 122.6 | Q34: 113.1 | R34: 114.2 | S34: 111.9 | T34: 113.8 | U34: 111.1 | V34: 111.6 | W34: 111.1 | X34: 109.3 | Y34: 109.5 | Z34: 108.6 | AA34: 111.2 | AB34: 108.1 | AC34: 109.7 | AD34: 116.3 | AG34: =SUM(D34:P34) -> 1538.8 | AH34: =SUM(Q34) -> 113.1 | AI34: =SUM(R34:T34) -> 339.9 | AJ34: =SUM(U34:W34) -> 333.8 | AK34: =SUM(X34,AA34,AB34) -> 328.6 | AL34: =SUM(Y34) -> 109.5 | AM34: =SUM(Z34) -> 108.6 | AN34: =SUM(AC34) -> 109.7
A35: Rural | B35: 2013 | C35: December | D35: 118.4 | E35: 115.9 | F35: 120.4 | G35: 113.8 | H35: 109.5 | I35: 115.5 | J35: 145.7 | K35: 109.5 | L35: 102.9 | M35: 109.8 | N35: 112.1 | O35: 116.8 | P35: 118.7 | Q35: 113.6 | R35: 115.8 | S35: 114 | T35: 115.5 | U35: NA | V35: 112.8 | W35: 112.1 | X35: 110.1 | Y35: 109.9 | Z35: 109.2 | AA35: 111.6 | AB35: 108.1 | AC35: 110.1 | AD35: 115.5 | AG35: =SUM(D35:P35) -> 1509 | AH35: =SUM(Q35) -> 113.6 | AI35: =SUM(R35:T35) -> 345.3 | AJ35: =SUM(U35:W35) -> 224.9 | AK35: =SUM(X35,AA35,AB35) -> 329.8 | AL35: =SUM(Y35) -> 109.9 | AM35: =SUM(Z35) -> 109.2 | AN35: =SUM(AC35) -> 110.1
A36: Urban | B36: 2013 | C36: December | D36: 120.5 | E36: 118.1 | F36: 128.5 | G36: 112.8 | H36: 103.4 | I36: 110.7 | J36: 144.8 | K36: 107.1 | L36: 98.6 | M36: 111.9 | N36: 112.1 | O36: 118.1 | P36: 117.8 | Q36: 115 | R36: 114.2 | S36: 110.9 | T36: 113.7 | U36: 110.7 | V36: 110.4 | W36: 111.3 | X36: 109 | Y36: 109.7 | Z36: 108.9 | AA36: 111.4 | AB36: 107.7 | AC36: 109.8 | AD36: 113.3 | AG36: =SUM(D36:P36) -> 1504.4 | AH36: =SUM(Q36) -> 115 | AI36: =SUM(R36:T36) -> 338.8 | AJ36: =SUM(U36:W36) -> 332.4 | AK36: =SUM(X36,AA36,AB36) -> 328.1 | AL36: =SUM(Y36) -> 109.7 | AM36: =SUM(Z36) -> 108.9 | AN36: =SUM(AC36) -> 109.8
A37: Rural+Urban | B37: 2013 | C37: December | D37: 119.1 | E37: 116.7 | F37: 123.5 | G37: 113.4 | H37: 107.3 | I37: 113.3 | J37: 145.4 | K37: 108.7 | L37: 101.5 | M37: 110.5 | N37: 112.1 | O37: 117.4 | P37: 118.4 | Q37: 114 | R37: 115.2 | S37: 112.7 | T37: 114.8 | U37: 110.7 | V37: 111.9 | W37: 111.7 | X37: 109.7 | Y37: 109.8 | Z37: 109 | AA37: 111.5 | AB37: 107.9 | AC37: 110 | AD37: 114.5 | AG37: =SUM(D37:P37) -> 1507.3 | AH37: =SUM(Q37) -> 114 | AI37: =SUM(R37:T37) -> 342.7 | AJ37: =SUM(U37:W37) -> 334.3 | AK37: =SUM(X37,AA37,AB37) -> 329.1 | AL37: =SUM(Y37) -> 109.8 | AM37: =SUM(Z37) -> 109 | AN37: =SUM(AC37) -> 110
A38: Rural | B38: 2014 | C38: January | D38: 118.9 | E38: 117.1 | F38: 120.5 | G38: 114.4 | H38: 109 | I38: 115.5 | J38: 123.9 | K38: 109.6 | L38: 101.8 | M38: 110.2 | N38: 112.4 | O38: 117.3 | P38: 116 | Q38: 114 | R38: 116.5 | S38: 114.5 | T38: 116.2 | U38: NA | V38: 113 | W38: 112.6 | X38: 110.6 | Y38: 110.5 | Z38: 109.6 | AA38: 111.8 | AB38: 108.3 | AC38: 110.6 | AD38: 114.2 | AG38: =SUM(D38:P38) -> 1486.6 | AH38: =SUM(Q38) -> 114 | AI38: =SUM(R38:T38) -> 347.2 | AJ38: =SUM(U38:W38) -> 225.6 | AK38: =SUM(X38,AA38,AB38) -> 330.7 | AL38: =SUM(Y38) -> 110.5 | AM38: =SUM(Z38) -> 109.6 | AN38: =SUM(AC38) -> 110.6
A39: Urban | B39: 2014 | C39: January | D39: 121.2 | E39: 122 | F39: 129.9 | G39: 113.6 | H39: 102.9 | I39: 112.1 | J39: 118.9 | K39: 107.5 | L39: 96.9 | M39: 112.7 | N39: 112.1 | O39: 119 | P39: 115.5 | Q39: 115.7 | R39: 114.8 | S39: 111.3 | T39: 114.3 | U39: 111.6 | V39: 111 | W39: 111.9 | X39: 109.7 | Y39: 110.8 | Z39: 109.8 | AA39: 111.5 | AB39: 108 | AC39: 110.5 | AD39: 112.9 | AG39: =SUM(D39:P39) -> 1484.3 | AH39: =SUM(Q39) -> 115.7 | AI39: =SUM(R39:T39) -> 340.4 | AJ39: =SUM(U39:W39) -> 334.5 | AK39: =SUM(X39,AA39,AB39) -> 329.2 | AL39: =SUM(Y39) -> 110.8 | AM39: =SUM(Z39) -> 109.8 | AN39: =SUM(AC39) -> 110.5
A40: Rural+Urban | B40: 2014 | C40: January | D40: 119.6 | E40: 118.8 | F40: 124.1 | G40: 114.1 | H40: 106.8 | I40: 113.9 | J40: 122.2 | K40: 108.9 | L40: 100.2 | M40: 111 | N40: 112.3 | O40: 118.1 | P40: 115.8 | Q40: 114.5 | R40: 115.8 | S40: 113.2 | T40: 115.4 | U40: 111.6 | V40: 112.2 | W40: 112.3 | X40: 110.3 | Y40: 110.7 | Z40: 109.7 | AA40: 111.6 | AB40: 108.2 | AC40: 110.6 | AD40: 113.6 | AG40: =SUM(D40:P40) -> 1485.8 | AH40: =SUM(Q40) -> 114.5 | AI40: =SUM(R40:T40) -> 344.4 | AJ40: =SUM(U40:W40) -> 336.1 | AK40: =SUM(X40,AA40,AB40) -> 330.1 | AL40: =SUM(Y40) -> 110.7 | AM40: =SUM(Z40) -> 109.7 | AN40: =SUM(AC40) -> 110.6
...

Sheet EXP
A1: Sector | B1: Year | C1: Month | D1: Cereals and products | E1: Meat and fish | F1: Egg | G1: Milk and products | H1: Oils and fats | I1: Fruits | J1: Vegetables | K1: Pulses and products | L1: Sugar and Confectionery | M1: Spices | N1: Non-alcoholic beverages | O1: Prepared meals, snacks, sweets etc. | P1: Food and beverages | Q1: Pan, tobacco and intoxicants | R1: Clothing | S1: Footwear | T1: Clothing and footwear | U1: Housing | V1: Fuel and light | W1: Household goods and services | X1: Health | Y1: Transport and communication | Z1: Recreation and amusement | AA1: Education | AB1: Personal care and effects | AC1: Miscellaneous | AD1: General index | AE1: FOOD & NON-ALCHOLIC BEVERAGES | AF1: ALCOHOL,TOBACCO & INTOXICANTS | AG1: CLOTHING AND FOOTWEAR | AH1: HOUSING,FUEL AND UTILITIES | AI1: HEALTHCARE AND EDUCATION | AJ1: TRANSPORT & COMMUNICATION | AK1: RECREATION AND CULTURE | AL1: MISCELLANEOUS
A2: Rural | B2: 2013 | C2: January | D2: 107.5 | E2: 106.3 | F2: 108.1 | G2: 104.9 | H2: 106.1 | I2: 103.9 | J2: 101.9 | K2: 106.1 | L2: 106.8 | M2: 103.1 | N2: 104.8 | O2: 106.7 | P2: 105.5 | Q2: 105.1 | R2: 106.5 | S2: 105.8 | T2: 106.4 | U2: NA | V2: 105.5 | W2: 104.8 | X2: 104 | Y2: 103.3 | Z2: 103.4 | AA2: 103.8 | AB2: 104.7 | AC2: 104 | AD2: 105.1 | AE2: =SUM(D2:P2) -> 1371.7 | AF2: =SUM(Q2) -> 105.1 | AG2: =SUM(R2:T2) -> 318.7 | AH2: =SUM(U2:W2) -> 210.3 | AI2: =SUM(X2,AA2,AB2) -> 312.5 | AJ2: =SUM(Y2) -> 103.3 | AK2: =SUM(Z2) -> 103.4 | AL2: =SUM(AC2) -> 104
A3: Urban | B3: 2013 | C3: January | D3: 110.5 | E3: 109.1 | F3: 113 | G3: 103.6 | H3: 103.4 | I3: 102.3 | J3: 102.9 | K3: 105.8 | L3: 105.1 | M3: 101.8 | N3: 105.1 | O3: 107.9 | P3: 105.9 | Q3: 105.2 | R3: 105.9 | S3: 105 | T3: 105.8 | U3: 100.3 | V3: 105.4 | W3: 104.8 | X3: 104.1 | Y3: 103.2 | Z3: 102.9 | AA3: 103.5 | AB3: 104.3 | AC3: 103.7 | AD3: 104 | AE3: =SUM(D3:P3) -> 1376.4 | AF3: =SUM(Q3) -> 105.2 | AG3: =SUM(R3:T3) -> 316.7 | AH3: =SUM(U3:W3) -> 310.5 | AI3: =SUM(X3,AA3,AB3) -> 311.9 | AJ3: =SUM(Y3) -> 103.2 | AK3: =SUM(Z3) -> 102.9 | AL3: =SUM(AC3) -> 103.7
A4: Rural+Urban | B4: 2013 | C4: January | D4: 108.4 | E4: 107.3 | F4: 110 | G4: 104.4 | H4: 105.1 | I4: 103.2 | J4: 102.2 | K4: 106 | L4: 106.2 | M4: 102.7 | N4: 104.9 | O4: 107.3 | P4: 105.6 | Q4: 105.1 | R4: 106.3 | S4: 105.5 | T4: 106.2 | U4: 100.3 | V4: 105.5 | W4: 104.8 | X4: 104 | Y4: 103.2 | Z4: 103.1 | AA4: 103.6 | AB4: 104.5 | AC4: 103.9 | AD4: 104.6 | AE4: =SUM(D4:P4) -> 1373.3 | AF4: =SUM(Q4) -> 105.1 | AG4: =SUM(R4:T4) -> 318 | AH4: =SUM(U4:W4) -> 310.6 | AI4: =SUM(X4,AA4,AB4) -> 312.1 | AJ4: =SUM(Y4) -> 103.2 | AK4: =SUM(Z4) -> 103.1 | AL4: =SUM(AC4) -> 103.9
A5: Rural | B5: 2013 | C5: February | D5: 109.2 | E5: 108.7 | F5: 110.2 | G5: 105.4 | H5: 106.7 | I5: 104 | J5: 102.4 | K5: 105.9 | L5: 105.7 | M5: 103.1 | N5: 105.1 | O5: 107.7 | P5: 106.3 | Q5: 105.6 | R5: 107.1 | S5: 106.3 | T5: 107 | U5: NA | V5: 106.2 | W5: 105.2 | X5: 104.4 | Y5: 103.9 | Z5: 104 | AA5: 104.1 | AB5: 104.6 | AC5: 104.4 | AD5: 105.8 | AE5: =SUM(D5:P5) -> 1380.4 | AF5: =SUM(Q5) -> 105.6 | AG5: =SUM(R5:T5) -> 320.4 | AH5: =SUM(U5:W5) -> 211.4 | AI5: =SUM(X5,AA5,AB5) -> 313.1 | AJ5: =SUM(Y5) -> 103.9 | AK5: =SUM(Z5) -> 104 | AL5: =SUM(AC5) -> 104.4
A6: Urban | B6: 2013 | C6: February | D6: 112.9 | E6: 112.9 | F6: 116.9 | G6: 104 | H6: 103.5 | I6: 103.1 | J6: 104.9 | K6: 104.1 | L6: 103.8 | M6: 102.3 | N6: 106 | O6: 109 | P6: 107.2 | Q6: 106 | R6: 106.6 | S6: 105.5 | T6: 106.4 | U6: 100.4 | V6: 105.7 | W6: 105.2 | X6: 104.7 | Y6: 104.4 | Z6: 103.3 | AA6: 103.7 | AB6: 104.3 | AC6: 104.3 | AD6: 104.7 | AE6: =SUM(D6:P6) -> 1390.6 | AF6: =SUM(Q6) -> 106 | AG6: =SUM(R6:T6) -> 318.5 | AH6: =SUM(U6:W6) -> 311.3 | AI6: =SUM(X6,AA6,AB6) -> 312.7 | AJ6: =SUM(Y6) -> 104.4 | AK6: =SUM(Z6) -> 103.3 | AL6: =SUM(AC6) -> 104.3
A7: Rural+Urban | B7: 2013 | C7: February | D7: 110.4 | E7: 110.2 | F7: 112.8 | G7: 104.9 | H7: 105.5 | I7: 103.6 | J7: 103.2 | K7: 105.3 | L7: 105.1 | M7: 102.8 | N7: 105.5 | O7: 108.3 | P7: 106.6 | Q7: 105.7 | R7: 106.9 | S7: 106 | T7: 106.8 | U7: 100.4 | V7: 106 | W7: 105.2 | X7: 104.5 | Y7: 104.2 | Z7: 103.6 | AA7: 103.9 | AB7: 104.5 | AC7: 104.4 | AD7: 105.3 | AE7: =SUM(D7:P7) -> 1384.2 | AF7: =SUM(Q7) -> 105.7 | AG7: =SUM(R7:T7) -> 319.7 | AH7: =SUM(U7:W7) -> 311.6 | AI7: =SUM(X7,AA7,AB7) -> 312.9 | AJ7: =SUM(Y7) -> 104.2 | AK7: =SUM(Z7) -> 103.6 | AL7: =SUM(AC7) -> 104.4
A8: Rural | B8: 2013 | C8: March | D8: 110.2 | E8: 108.8 | F8: 109.9 | G8: 105.6 | H8: 106.2 | I8: 105.7 | J8: 101.4 | K8: 105.7 | L8: 105 | M8: 103.3 | N8: 105.6 | O8: 108.2 | P8: 106.6 | Q8: 106.5 | R8: 107.6 | S8: 106.8 | T8: 107.5 | U8: NA | V8: 106.1 | W8: 105.6 | X8: 104.7 | Y8: 104.6 | Z8: 104 | AA8: 104.3 | AB8: 104.3 | AC8: 104.6 | AD8: 106 | AE8: =SUM(D8:P8) -> 1382.2 | AF8: =SUM(Q8) -> 106.5 | AG8: =SUM(R8:T8) -> 321.9 | AH8: =SUM(U8:W8) -> 211.7 | AI8: =SUM(X8,AA8,AB8) -> 313.3 | AJ8: =SUM(Y8) -> 104.6 | AK8: =SUM(Z8) -> 104 | AL8: =SUM(AC8) -> 104.6
A9: Urban | B9: 2013 | C9: March | D9: 113.9 | E9: 111.4 | F9: 113.2 | G9: 104.3 | H9: 102.7 | I9: 104.9 | J9: 103.8 | K9: 103.5 | L9: 102.6 | M9: 102.4 | N9: 107 | O9: 109.8 | P9: 107.3 | Q9: 106.8 | R9: 107.2 | S9: 106 | T9: 107 | U9: 100.4 | V9: 106 | W9: 105.7 | X9: 105.2 | Y9: 105.5 | Z9: 103.5 | AA9: 103.8 | AB9: 104.2 | AC9: 104.9 | AD9: 105 | AE9: =SUM(D9:P9) -> 1386.8 | AF9: =SUM(Q9) -> 106.8 | AG9: =SUM(R9:T9) -> 320.2 | AH9: =SUM(U9:W9) -> 312.1 | AI9: =SUM(X9,AA9,AB9) -> 313.2 | AJ9: =SUM(Y9) -> 105.5 | AK9: =SUM(Z9) -> 103.5 | AL9: =SUM(AC9) -> 104.9
A10: Rural+Urban | B10: 2013 | C10: March | D10: 111.4 | E10: 109.7 | F10: 111.2 | G10: 105.1 | H10: 104.9 | I10: 105.3 | J10: 102.2 | K10: 105 | L10: 104.2 | M10: 103 | N10: 106.2 | O10: 108.9 | P10: 106.9 | Q10: 106.6 | R10: 107.4 | S10: 106.5 | T10: 107.3 | U10: 100.4 | V10: 106.1 | W10: 105.6 | X10: 104.9 | Y10: 105.1 | Z10: 103.7 | AA10: 104 | AB10: 104.3 | AC10: 104.7 | AD10: 105.5 | AE10: =SUM(D10:P10) -> 1384 | AF10: =SUM(Q10) -> 106.6 | AG10: =SUM(R10:T10) -> 321.2 | AH10: =SUM(U10:W10) -> 312.1 | AI10: =SUM(X10,AA10,AB10) -> 313.2 | AJ10: =SUM(Y10) -> 105.1 | AK10: =SUM(Z10) -> 103.7 | AL10: =SUM(AC10) -> 104.7
A11: Rural | B11: 2013 | C11: April | D11: 110.2 | E11: 109.5 | F11: 106.9 | G11: 106.3 | H11: 105.7 | I11: 108.3 | J11: 103.4 | K11: 105.7 | L11: 104.2 | M11: 103.2 | N11: 106.5 | O11: 108.8 | P11: 107.1 | Q11: 107.1 | R11: 108.1 | S11: 107.4 | T11: 108 | U11: NA | V11: 106.5 | W11: 106.1 | X11: 105.1 | Y11: 104.4 | Z11: 104.5 | AA11: 104.8 | AB11: 102.7 | AC11: 104.6 | AD11: 106.4 | AE11: =SUM(D11:P11) -> 1385.8 | AF11: =SUM(Q11) -> 107.1 | AG11: =SUM(R11:T11) -> 323.5 | AH11: =SUM(U11:W11) -> 212.6 | AI11: =SUM(X11,AA11,AB11) -> 312.6 | AJ11: =SUM(Y11) -> 104.4 | AK11: =SUM(Z11) -> 104.5 | AL11: =SUM(AC11) -> 104.6
A12: Urban | B12: 2013 | C12: April | D12: 114.6 | E12: 113.4 | F12: 106 | G12: 104.7 | H12: 102.1 | I12: 109.5 | J12: 109.7 | K12: 104.6 | L12: 102 | M12: 103.5 | N12: 108.2 | O12: 110.6 | P12: 108.8 | Q12: 108.5 | R12: 107.9 | S12: 106.4 | T12: 107.7 | U12: 100.5 | V12: 106.4 | W12: 106.5 | X12: 105.7 | Y12: 105 | Z12: 104 | AA12: 105.2 | AB12: 103.2 | AC12: 105.1 | AD12: 105.7 | AE12: =SUM(D12:P12) -> 1397.7 | AF12: =SUM(Q12) -> 108.5 | AG12: =SUM(R12:T12) -> 322 | AH12: =SUM(U12:W12) -> 313.4 | AI12: =SUM(X12,AA12,AB12) -> 314.1 | AJ12: =SUM(Y12) -> 105 | AK12: =SUM(Z12) -> 104 | AL12: =SUM(AC12) -> 105.1
A13: Rural+Urban | B13: 2013 | C13: April | D13: 111.6 | E13: 110.9 | F13: 106.6 | G13: 105.7 | H13: 104.4 | I13: 108.9 | J13: 105.5 | K13: 105.3 | L13: 103.5 | M13: 103.3 | N13: 107.2 | O13: 109.6 | P13: 107.7 | Q13: 107.5 | R13: 108 | S13: 107 | T13: 107.9 | U13: 100.5 | V13: 106.5 | W13: 106.3 | X13: 105.3 | Y13: 104.7 | Z13: 104.2 | AA13: 105 | AB13: 102.9 | AC13: 104.8 | AD13: 106.1 | AE13: =SUM(D13:P13) -> 1390.2 | AF13: =SUM(Q13) -> 107.5 | AG13: =SUM(R13:T13) -> 322.9 | AH13: =SUM(U13:W13) -> 313.3 | AI13: =SUM(X13,AA13,AB13) -> 313.2 | AJ13: =SUM(Y13) -> 104.7 | AK13: =SUM(Z13) -> 104.2 | AL13: =SUM(AC13) -> 104.8
A14: Rural | B14: 2013 | C14: May | D14: 110.9 | E14: 109.8 | F14: 105.9 | G14: 107.5 | H14: 105.3 | I14: 108.1 | J14: 107.3 | K14: 106.1 | L14: 103.7 | M14: 104 | N14: 107.4 | O14: 109.9 | P14: 108.1 | Q14: 108.1 | R14: 108.8 | S14: 107.9 | T14: 108.6 | U14: NA | V14: 107.5 | W14: 106.8 | X14: 105.7 | Y14: 104.1 | Z14: 105 | AA14: 105.5 | AB14: 102.1 | AC14: 104.8 | AD14: 107.2 | AE14: =SUM(D14:P14) -> 1394 | AF14: =SUM(Q14) -> 108.1 | AG14: =SUM(R14:T14) -> 325.3 | AH14: =SUM(U14:W14) -> 214.3 | AI14: =SUM(X14,AA14,AB14) -> 313.3 | AJ14: =SUM(Y14) -> 104.1 | AK14: =SUM(Z14) -> 105 | AL14: =SUM(AC14) -> 104.8
A15: Urban | B15: 2013 | C15: May | D15: 115.4 | E15: 114.2 | F15: 102.7 | G15: 105.5 | H15: 101.5 | I15: 110.6 | J15: 123.7 | K15: 105.2 | L15: 101.9 | M15: 105 | N15: 109.1 | O15: 111.3 | P15: 111.1 | Q15: 109.8 | R15: 108.5 | S15: 106.7 | T15: 108.3 | U15: 100.5 | V15: 107.2 | W15: 107.1 | X15: 106.2 | Y15: 103.9 | Z15: 104.6 | AA15: 105.7 | AB15: 102.6 | AC15: 104.9 | AD15: 106.6 | AE15: =SUM(D15:P15) -> 1417.2 | AF15: =SUM(Q15) -> 109.8 | AG15: =SUM(R15:T15) -> 323.5 | AH15: =SUM(U15:W15) -> 314.8 | AI15: =SUM(X15,AA15,AB15) -> 314.5 | AJ15: =SUM(Y15) -> 103.9 | AK15: =SUM(Z15) -> 104.6 | AL15: =SUM(AC15) -> 104.9
A16: Rural+Urban | B16: 2013 | C16: May | D16: 112.3 | E16: 111.3 | F16: 104.7 | G16: 106.8 | H16: 103.9 | I16: 109.3 | J16: 112.9 | K16: 105.8 | L16: 103.1 | M16: 104.3 | N16: 108.1 | O16: 110.5 | P16: 109.2 | Q16: 108.6 | R16: 108.7 | S16: 107.4 | T16: 108.5 | U16: 100.5 | V16: 107.4 | W16: 106.9 | X16: 105.9 | Y16: 104 | Z16: 104.8 | AA16: 105.6 | AB16: 102.3 | AC16: 104.8 | AD16: 106.9 | AE16: =SUM(D16:P16) -> 1402.2 | AF16: =SUM(Q16) -> 108.6 | AG16: =SUM(R16:T16) -> 324.6 | AH16: =SUM(U16:W16) -> 314.8 | AI16: =SUM(X16,AA16,AB16) -> 313.8 | AJ16: =SUM(Y16) -> 104 | AK16: =SUM(Z16) -> 104.8 | AL16: =SUM(AC16) -> 104.8
A17: Rural | B17: 2013 | C17: June | D17: 112.3 | E17: 112.1 | F17: 108.1 | G17: 108.3 | H17: 105.9 | I17: 109.2 | J17: 118 | K17: 106.8 | L17: 104.1 | M17: 105.4 | N17: 108.2 | O17: 111 | P17: 110.6 | Q17: 109 | R17: 109.7 | S17: 108.8 | T17: 109.5 | U17: NA | V17: 108.5 | W17: 107.5 | X17: 106.3 | Y17: 105 | Z17: 105.6 | AA17: 106.5 | AB17: 102.5 | AC17: 105.5 | AD17: 108.9 | AE17: =SUM(D17:P17) -> 1420 | AF17: =SUM(Q17) -> 109 | AG17: =SUM(R17:T17) -> 328 | AH17: =SUM(U17:W17) -> 216 | AI17: =SUM(X17,AA17,AB17) -> 315.3 | AJ17: =SUM(Y17) -> 105 | AK17: =SUM(Z17) -> 105.6 | AL17: =SUM(AC17) -> 105.5
A18: Urban | B18: 2013 | C18: June | D18: 117 | E18: 120.1 | F18: 112.5 | G18: 107.3 | H18: 101.3 | I18: 112.4 | J18: 143.6 | K18: 105.4 | L18: 101.4 | M18: 106.4 | N18: 110 | O18: 112.2 | P18: 115 | Q18: 110.9 | R18: 109.2 | S18: 107.2 | T18: 108.9 | U18: 106.6 | V18: 108 | W18: 107.7 | X18: 106.5 | Y18: 105.2 | Z18: 105.2 | AA18: 108.1 | AB18: 103.3 | AC18: 106.1 | AD18: 109.7 | AE18: =SUM(D18:P18) -> 1464.6 | AF18: =SUM(Q18) -> 110.9 | AG18: =SUM(R18:T18) -> 325.3 | AH18: =SUM(U18:W18) -> 322.3 | AI18: =SUM(X18,AA18,AB18) -> 317.9 | AJ18: =SUM(Y18) -> 105.2 | AK18: =SUM(Z18) -> 105.2 | AL18: =SUM(AC18) -> 106.1
A19: Rural+Urban | B19: 2013 | C19: June | D19: 113.8 | E19: 114.9 | F19: 109.8 | G19: 107.9 | H19: 104.2 | I19: 110.7 | J19: 126.7 | K19: 106.3 | L19: 103.2 | M19: 105.7 | N19: 109 | O19: 111.6 | P19: 112.2 | Q19: 109.5 | R19: 109.5 | S19: 108.1 | T19: 109.3 | U19: 106.6 | V19: 108.3 | W19: 107.6 | X19: 106.4 | Y19: 105.1 | Z19: 105.4 | AA19: 107.4 | AB19: 102.8 | AC19: 105.8 | AD19: 109.3 | AE19: =SUM(D19:P19) -> 1436 | AF19: =SUM(Q19) -> 109.5 | AG19: =SUM(R19:T19) -> 326.9 | AH19: =SUM(U19:W19) -> 322.5 | AI19: =SUM(X19,AA19,AB19) -> 316.6 | AJ19: =SUM(Y19) -> 105.1 | AK19: =SUM(Z19) -> 105.4 | AL19: =SUM(AC19) -> 105.8
A20: Rural | B20: 2013 | C20: July | D20: 113.4 | E20: 114.9 | F20: 110.5 | G20: 109.3 | H20: 106.2 | I20: 110.3 | J20: 129.2 | K20: 107.1 | L20: 104.3 | M20: 106.4 | N20: 109.1 | O20: 112.1 | P20: 113.1 | Q20: 109.8 | R20: 110.5 | S20: 109.5 | T20: 110.3 | U20: NA | V20: 109.5 | W20: 108.3 | X20: 106.9 | Y20: 106.8 | Z20: 106.4 | AA20: 107.8 | AB20: 102.5 | AC20: 106.5 | AD20: 110.7 | AE20: =SUM(D20:P20) -> 1445.9 | AF20: =SUM(Q20) -> 109.8 | AG20: =SUM(R20:T20) -> 330.3 | AH20: =SUM(U20:W20) -> 217.8 | AI20: =SUM(X20,AA20,AB20) -> 317.2 | AJ20: =SUM(Y20) -> 106.8 | AK20: =SUM(Z20) -> 106.4 | AL20: =SUM(AC20) -> 106.5
A21: Urban | B21: 2013 | C21: July | D21: 117.8 | E21: 119.2 | F21: 114 | G21: 108.3 | H21: 101.1 | I21: 113.2 | J21: 160.9 | K21: 105.1 | L21: 101.3 | M21: 107.5 | N21: 110.4 | O21: 113.1 | P21: 117.5 | Q21: 111.7 | R21: 109.8 | S21: 107.8 | T21: 109.5 | U21: 107.7 | V21: 108.6 | W21: 108.1 | X21: 107.1 | Y21: 107.3 | Z21: 105.9 | AA21: 110.1 | AB21: 103.2 | AC21: 107.3 | AD21: 111.4 | AE21: =SUM(D21:P21) -> 1489.4 | AF21: =SUM(Q21) -> 111.7 | AG21: =SUM(R21:T21) -> 327.1 | AH21: =SUM(U21:W21) -> 324.4 | AI21: =SUM(X21,AA21,AB21) -> 320.4 | AJ21: =SUM(Y21) -> 107.3 | AK21: =SUM(Z21) -> 105.9 | AL21: =SUM(AC21) -> 107.3
A22: Rural+Urban | B22: 2013 | C22: July | D22: 114.8 | E22: 116.4 | F22: 111.9 | G22: 108.9 | H22: 104.3 | I22: 111.7 | J22: 140 | K22: 106.4 | L22: 103.3 | M22: 106.8 | N22: 109.6 | O22: 112.6 | P22: 114.7 | Q22: 110.3 | R22: 110.2 | S22: 108.8 | T22: 110 | U22: 107.7 | V22: 109.2 | W22: 108.2 | X22: 107 | Y22: 107.1 | Z22: 106.1 | AA22: 109.1 | AB22: 102.8 | AC22: 106.9 | AD22: 111 | AE22: =SUM(D22:P22) -> 1461.4 | AF22: =SUM(Q22) -> 110.3 | AG22: =SUM(R22:T22) -> 329 | AH22: =SUM(U22:W22) -> 325.1 | AI22: =SUM(X22,AA22,AB22) -> 318.9 | AJ22: =SUM(Y22) -> 107.1 | AK22: =SUM(Z22) -> 106.1 | AL22: =SUM(AC22) -> 106.9
A23: Rural | B23: 2013 | C23: August | D23: 114.3 | E23: 115.4 | F23: 111.1 | G23: 110 | H23: 106.4 | I23: 110.8 | J23: 138.9 | K23: 107.4 | L23: 104.1 | M23: 106.9 | N23: 109.7 | O23: 112.6 | P23: 114.9 | Q23: 110.7 | R23: 111.3 | S23: 110.2 | T23: 111.1 | U23: NA | V23: 109.9 | W23: 108.7 | X23: 107.5 | Y23: 107.8 | Z23: 106.8 | AA23: 108.7 | AB23: 105 | AC23: 107.5 | AD23: 112.1 | AE23: =SUM(D23:P23) -> 1462.5 | AF23: =SUM(Q23) -> 110.7 | AG23: =SUM(R23:T23) -> 332.6 | AH23: =SUM(U23:W23) -> 218.6 | AI23: =SUM(X23,AA23,AB23) -> 321.2 | AJ23: =SUM(Y23) -> 107.8 | AK23: =SUM(Z23) -> 106.8 | AL23: =SUM(AC23) -> 107.5
A24: Urban | B24: 2013 | C24: August | D24: 118.3 | E24: 120.4 | F24: 112.7 | G24: 108.9 | H24: 101.1 | I24: 108.7 | J24: 177 | K24: 104.7 | L24: 101 | M24: 108.5 | N24: 110.9 | O24: 114.3 | P24: 119.6 | Q24: 112.4 | R24: 110.6 | S24: 108.3 | T24: 110.2 | U24: 108.9 | V24: 109.3 | W24: 108.7 | X24: 107.6 | Y24: 108.1 | Z24: 106.5 | AA24: 110.8 | AB24: 106 | AC24: 108.3 | AD24: 112.7 | AE24: =SUM(D24:P24) -> 1506.1 | AF24: =SUM(Q24) -> 112.4 | AG24: =SUM(R24:T24) -> 329.1 | AH24: =SUM(U24:W24) -> 326.9 | AI24: =SUM(X24,AA24,AB24) -> 324.4 | AJ24: =SUM(Y24) -> 108.1 | AK24: =SUM(Z24) -> 106.5 | AL24: =SUM(AC24) -> 108.3
A25: Rural+Urban | B25: 2013 | C25: August | D25: 115.6 | E25: 117.2 | F25: 111.7 | G25: 109.6 | H25: 104.5 | I25: 109.8 | J25: 151.8 | K25: 106.5 | L25: 103.1 | M25: 107.4 | N25: 110.2 | O25: 113.4 | P25: 116.6 | Q25: 111.2 | R25: 111 | S25: 109.4 | T25: 110.7 | U25: 108.9 | V25: 109.7 | W25: 108.7 | X25: 107.5 | Y25: 108 | Z25: 106.6 | AA25: 109.9 | AB25: 105.4 | AC25: 107.9 | AD25: 112.4 | AE25: =SUM(D25:P25) -> 1477.4 | AF25: =SUM(Q25) -> 111.2 | AG25: =SUM(R25:T25) -> 331.1 | AH25: =SUM(U25:W25) -> 327.3 | AI25: =SUM(X25,AA25,AB25) -> 322.8 | AJ25: =SUM(Y25) -> 108 | AK25: =SUM(Z25) -> 106.6 | AL25: =SUM(AC25) -> 107.9
A26: Rural | B26: 2013 | C26: September | D26: 115.4 | E26: 115.7 | F26: 111.7 | G26: 111 | H26: 107.4 | I26: 110.9 | J26: 154 | K26: 108.1 | L26: 104.2 | M26: 107.9 | N26: 110.4 | O26: 114 | P26: 117.8 | Q26: 111.7 | R26: 112.7 | S26: 111.4 | T26: 112.5 | U26: NA | V26: 111.1 | W26: 109.6 | X26: 108.3 | Y26: 109.3 | Z26: 107.7 | AA26: 109.8 | AB26: 106.7 | AC26: 108.7 | AD26: 114.2 | AE26: =SUM(D26:P26) -> 1488.5 | AF26: =SUM(Q26) -> 111.7 | AG26: =SUM(R26:T26) -> 336.6 | AH26: =SUM(U26:W26) -> 220.7 | AI26: =SUM(X26,AA26,AB26) -> 324.8 | AJ26: =SUM(Y26) -> 109.3 | AK26: =SUM(Z26) -> 107.7 | AL26: =SUM(AC26) -> 108.7
A27: Urban | B27: 2013 | C27: September | D27: 118.6 | E27: 119.1 | F27: 113.2 | G27: 109.6 | H27: 101.7 | I27: 103.2 | J27: 174.3 | K27: 105.1 | L27: 100.8 | M27: 109.1 | N27: 111.1 | O27: 115.4 | P27: 119.2 | Q27: 112.9 | R27: 111.4 | S27: 109 | T27: 111.1 | U27: 109.7 | V27: 109.5 | W27: 109.6 | X27: 107.9 | Y27: 110.4 | Z27: 107.4 | AA27: 111.2 | AB27: 106.9 | AC27: 109.4 | AD27: 113.2 | AE27: =SUM(D27:P27) -> 1500.4 | AF27: =SUM(Q27) -> 112.9 | AG27: =SUM(R27:T27) -> 331.5 | AH27: =SUM(U27:W27) -> 328.8 | AI27: =SUM(X27,AA27,AB27) -> 326 | AJ27: =SUM(Y27) -> 110.4 | AK27: =SUM(Z27) -> 107.4 | AL27: =SUM(AC27) -> 109.4
A28: Rural+Urban | B28: 2013 | C28: September | D28: 116.4 | E28: 116.9 | F28: 112.3 | G28: 110.5 | H28: 105.3 | I28: 107.3 | J28: 160.9 | K28: 107.1 | L28: 103.1 | M28: 108.3 | N28: 110.7 | O28: 114.6 | P28: 118.3 | Q28: 112 | R28: 112.2 | S28: 110.4 | T28: 111.9 | U28: 109.7 | V28: 110.5 | W28: 109.6 | X28: 108.1 | Y28: 109.9 | Z28: 107.5 | AA28: 110.6 | AB28: 106.8 | AC28: 109 | AD28: 113.7 | AE28: =SUM(D28:P28) -> 1491.7 | AF28: =SUM(Q28) -> 112 | AG28: =SUM(R28:T28) -> 334.5 | AH28: =SUM(U28:W28) -> 329.8 | AI28: =SUM(X28,AA28,AB28) -> 325.5 | AJ28: =SUM(Y28) -> 109.9 | AK28: =SUM(Z28) -> 107.5 | AL28: =SUM(AC28) -> 109
A29: Rural | B29: 2013 | C29: October | D29: 116.3 | E29: 115.4 | F29: 112.6 | G29: 111.7 | H29: 107.7 | I29: 113.2 | J29: 164.9 | K29: 108.3 | L29: 103.9 | M29: 108.2 | N29: 111.1 | O29: 114.9 | P29: 119.8 | Q29: 112.2 | R29: 113.6 | S29: 112.3 | T29: 113.4 | U29: NA | V29: 111.6 | W29: 110.4 | X29: 108.9 | Y29: 109.3 | Z29: 108.3 | AA29: 110.2 | AB29: 107.5 | AC29: 109.1 | AD29: 115.5 | AE29: =SUM(D29:P29) -> 1508 | AF29: =SUM(Q29) -> 112.2 | AG29: =SUM(R29:T29) -> 339.3 | AH29: =SUM(U29:W29) -> 222 | AI29: =SUM(X29,AA29,AB29) -> 326.6 | AJ29: =SUM(Y29) -> 109.3 | AK29: =SUM(Z29) -> 108.3 | AL29: =SUM(AC29) -> 109.1
A30: Urban | B30: 2013 | C30: October | D30: 118.9 | E30: 118.1 | F30: 114.5 | G30: 110.4 | H30: 102.3 | I30: 106.2 | J30: 183.5 | K30: 105.3 | L30: 100.2 | M30: 109.6 | N30: 111.4 | O30: 116 | P30: 120.8 | Q30: 113.5 | R30: 112.5 | S30: 109.7 | T30: 112 | U30: 110.5 | V30: 109.7 | W30: 110.2 | X30: 108.2 | Y30: 109.7 | Z30: 108 | AA30: 111.3 | AB30: 107.3 | AC30: 109.4 | AD30: 114 | AE30: =SUM(D30:P30) -> 1517.2 | AF30: =SUM(Q30) -> 113.5 | AG30: =SUM(R30:T30) -> 334.2 | AH30: =SUM(U30:W30) -> 330.4 | AI30: =SUM(X30,AA30,AB30) -> 326.8 | AJ30: =SUM(Y30) -> 109.7 | AK30: =SUM(Z30) -> 108 | AL30: =SUM(AC30) -> 109.4
A31: Rural+Urban | B31: 2013 | C31: October | D31: 117.1 | E31: 116.3 | F31: 113.3 | G31: 111.2 | H31: 105.7 | I31: 109.9 | J31: 171.2 | K31: 107.3 | L31: 102.7 | M31: 108.7 | N31: 111.2 | O31: 115.4 | P31: 120.2 | Q31: 112.5 | R31: 113.2 | S31: 111.2 | T31: 112.8 | U31: 110.5 | V31: 110.9 | W31: 110.3 | X31: 108.6 | Y31: 109.5 | Z31: 108.1 | AA31: 110.8 | AB31: 107.4 | AC31: 109.2 | AD31: 114.8 | AE31: =SUM(D31:P31) -> 1510.2 | AF31: =SUM(Q31) -> 112.5 | AG31: =SUM(R31:T31) -> 337.2 | AH31: =SUM(U31:W31) -> 331.7 | AI31: =SUM(X31,AA31,AB31) -> 326.8 | AJ31: =SUM(Y31) -> 109.5 | AK31: =SUM(Z31) -> 108.1 | AL31: =SUM(AC31) -> 109.2
A32: Rural | B32: 2013 | C32: November | D32: 117.3 | E32: 114.9 | F32: 116.2 | G32: 112.8 | H32: 108.9 | I32: 116.6 | J32: 178.1 | K32: 109.1 | L32: 103.6 | M32: 109 | N32: 111.8 | O32: 116 | P32: 122.5 | Q32: 112.8 | R32: 114.6 | S32: 113.1 | T32: 114.4 | U32: NA | V32: 112.6 | W32: 111.3 | X32: 109.7 | Y32: 109.6 | Z32: 108.7 | AA32: 111 | AB32: 108.2 | AC32: 109.8 | AD32: 117.4 | AE32: =SUM(D32:P32) -> 1536.8 | AF32: =SUM(Q32) -> 112.8 | AG32: =SUM(R32:T32) -> 342.1 | AH32: =SUM(U32:W32) -> 223.9 | AI32: =SUM(X32,AA32,AB32) -> 328.9 | AJ32: =SUM(Y32) -> 109.6 | AK32: =SUM(Z32) -> 108.7 | AL32: =SUM(AC32) -> 109.8
A33: Urban | B33: 2013 | C33: November | D33: 119.8 | E33: 116.3 | F33: 122.6 | G33: 112 | H33: 103.2 | I33: 110 | J33: 192.8 | K33: 106.3 | L33: 99.5 | M33: 110.3 | N33: 111.8 | O33: 117.1 | P33: 122.9 | Q33: 114.1 | R33: 113.5 | S33: 110.3 | T33: 113 | U33: 111.1 | V33: 110 | W33: 110.9 | X33: 108.6 | Y33: 109.5 | Z33: 108.5 | AA33: 111.3 | AB33: 107.9 | AC33: 109.6 | AD33: 115 | AE33: =SUM(D33:P33) -> 1544.6 | AF33: =SUM(Q33) -> 114.1 | AG33: =SUM(R33:T33) -> 336.8 | AH33: =SUM(U33:W33) -> 332 | AI33: =SUM(X33,AA33,AB33) -> 327.8 | AJ33: =SUM(Y33) -> 109.5 | AK33: =SUM(Z33) -> 108.5 | AL33: =SUM(AC33) -> 109.6
A34: Rural+Urban | B34: 2013 | C34: November | D34: 118.1 | E34: 115.4 | F34: 118.7 | G34: 112.5 | H34: 106.8 | I34: 113.5 | J34: 183.1 | K34: 108.2 | L34: 102.2 | M34: 109.4 | N34: 111.8 | O34: 116.5 | P34: 122.6 | Q34: 113.1 | R34: 114.2 | S34: 111.9 | T34: 113.8 | U34: 111.1 | V34: 111.6 | W34: 111.1 | X34: 109.3 | Y34: 109.5 | Z34: 108.6 | AA34: 111.2 | AB34: 108.1 | AC34: 109.7 | AD34: 116.3 | AE34: =SUM(D34:P34) -> 1538.8 | AF34: =SUM(Q34) -> 113.1 | AG34: =SUM(R34:T34) -> 339.9 | AH34: =SUM(U34:W34) -> 333.8 | AI34: =SUM(X34,AA34,AB34) -> 328.6 | AJ34: =SUM(Y34) -> 109.5 | AK34: =SUM(Z34) -> 108.6 | AL34: =SUM(AC34) -> 109.7
A35: Rural | B35: 2013 | C35: December | D35: 118.4 | E35: 115.9 | F35: 120.4 | G35: 113.8 | H35: 109.5 | I35: 115.5 | J35: 145.7 | K35: 109.5 | L35: 102.9 | M35: 109.8 | N35: 112.1 | O35: 116.8 | P35: 118.7 | Q35: 113.6 | R35: 115.8 | S35: 114 | T35: 115.5 | U35: NA | V35: 112.8 | W35: 112.1 | X35: 110.1 | Y35: 109.9 | Z35: 109.2 | AA35: 111.6 | AB35: 108.1 | AC35: 110.1 | AD35: 115.5 | AE35: =SUM(D35:P35) -> 1509 | AF35: =SUM(Q35) -> 113.6 | AG35: =SUM(R35:T35) -> 345.3 | AH35: =SUM(U35:W35) -> 224.9 | AI35: =SUM(X35,AA35,AB35) -> 329.8 | AJ35: =SUM(Y35) -> 109.9 | AK35: =SUM(Z35) -> 109.2 | AL35: =SUM(AC35) -> 110.1
A36: Urban | B36: 2013 | C36: December | D36: 120.5 | E36: 118.1 | F36: 128.5 | G36: 112.8 | H36: 103.4 | I36: 110.7 | J36: 144.8 | K36: 107.1 | L36: 98.6 | M36: 111.9 | N36: 112.1 | O36: 118.1 | P36: 117.8 | Q36: 115 | R36: 114.2 | S36: 110.9 | T36: 113.7 | U36: 110.7 | V36: 110.4 | W36: 111.3 | X36: 109 | Y36: 109.7 | Z36: 108.9 | AA36: 111.4 | AB36: 107.7 | AC36: 109.8 | AD36: 113.3 | AE36: =SUM(D36:P36) -> 1504.4 | AF36: =SUM(Q36) -> 115 | AG36: =SUM(R36:T36) -> 338.8 | AH36: =SUM(U36:W36) -> 332.4 | AI36: =SUM(X36,AA36,AB36) -> 328.1 | AJ36: =SUM(Y36) -> 109.7 | AK36: =SUM(Z36) -> 108.9 | AL36: =SUM(AC36) -> 109.8
A37: Rural+Urban | B37: 2013 | C37: December | D37: 119.1 | E37: 116.7 | F37: 123.5 | G37: 113.4 | H37: 107.3 | I37: 113.3 | J37: 145.4 | K37: 108.7 | L37: 101.5 | M37: 110.5 | N37: 112.1 | O37: 117.4 | P37: 118.4 | Q37: 114 | R37: 115.2 | S37: 112.7 | T37: 114.8 | U37: 110.7 | V37: 111.9 | W37: 111.7 | X37: 109.7 | Y37: 109.8 | Z37: 109 | AA37: 111.5 | AB37: 107.9 | AC37: 110 | AD37: 114.5 | AE37: =SUM(D37:P37) -> 1507.3 | AF37: =SUM(Q37) -> 114 | AG37: =SUM(R37:T37) -> 342.7 | AH37: =SUM(U37:W37) -> 334.3 | AI37: =SUM(X37,AA37,AB37) -> 329.1 | AJ37: =SUM(Y37) -> 109.8 | AK37: =SUM(Z37) -> 109 | AL37: =SUM(AC37) -> 110
A38: Rural | B38: 2014 | C38: January | D38: 118.9 | E38: 117.1 | F38: 120.5 | G38: 114.4 | H38: 109 | I38: 115.5 | J38: 123.9 | K38: 109.6 | L38: 101.8 | M38: 110.2 | N38: 112.4 | O38: 117.3 | P38: 116 | Q38: 114 | R38: 116.5 | S38: 114.5 | T38: 116.2 | U38: NA | V38: 113 | W38: 112.6 | X38: 110.6 | Y38: 110.5 | Z38: 109.6 | AA38: 111.8 | AB38: 108.3 | AC38: 110.6 | AD38: 114.2 | AE38: =SUM(D38:P38) -> 1486.6 | AF38: =SUM(Q38) -> 114 | AG38: =SUM(R38:T38) -> 347.2 | AH38: =SUM(U38:W38) -> 225.6 | AI38: =SUM(X38,AA38,AB38) -> 330.7 | AJ38: =SUM(Y38) -> 110.5 | AK38: =SUM(Z38) -> 109.6 | AL38: =SUM(AC38) -> 110.6
A39: Urban | B39: 2014 | C39: January | D39: 121.2 | E39: 122 | F39: 129.9 | G39: 113.6 | H39: 102.9 | I39: 112.1 | J39: 118.9 | K39: 107.5 | L39: 96.9 | M39: 112.7 | N39: 112.1 | O39: 119 | P39: 115.5 | Q39: 115.7 | R39: 114.8 | S39: 111.3 | T39: 114.3 | U39: 111.6 | V39: 111 | W39: 111.9 | X39: 109.7 | Y39: 110.8 | Z39: 109.8 | AA39: 111.5 | AB39: 108 | AC39: 110.5 | AD39: 112.9 | AE39: =SUM(D39:P39) -> 1484.3 | AF39: =SUM(Q39) -> 115.7 | AG39: =SUM(R39:T39) -> 340.4 | AH39: =SUM(U39:W39) -> 334.5 | AI39: =SUM(X39,AA39,AB39) -> 329.2 | AJ39: =SUM(Y39) -> 110.8 | AK39: =SUM(Z39) -> 109.8 | AL39: =SUM(AC39) -> 110.5
A40: Rural+Urban | B40: 2014 | C40: January | D40: 119.6 | E40: 118.8 | F40: 124.1 | G40: 114.1 | H40: 106.8 | I40: 113.9 | J40: 122.2 | K40: 108.9 | L40: 100.2 | M40: 111 | N40: 112.3 | O40: 118.1 | P40: 115.8 | Q40: 114.5 | R40: 115.8 | S40: 113.2 | T40: 115.4 | U40: 111.6 | V40: 112.2 | W40: 112.3 | X40: 110.3 | Y40: 110.7 | Z40: 109.7 | AA40: 111.6 | AB40: 108.2 | AC40: 110.6 | AD40: 113.6 | AE40: =SUM(D40:P40) -> 1485.8 | AF40: =SUM(Q40) -> 114.5 | AG40: =SUM(R40:T40) -> 344.4 | AH40: =SUM(U40:W40) -> 336.1 | AI40: =SUM(X40,AA40,AB40) -> 330.1 | AJ40: =SUM(Y40) -> 110.7 | AK40: =SUM(Z40) -> 109.7 | AL40: =SUM(AC40) -> 110.6
...

Sheet Q1
A1: Analysis of CPI Contribution by Major Consumption Categories Bucket
A6: SECTOR | B6: RURAL+URBAN
A7: YEAR | B7: 2022 | BE7: RURAL | BG7: 2013 | BH7: JANUARY
A8: MONTH | B8: OCTOBER | L8: RURAL | N8: 2013 | O8: JANUARY | BE8: URBAN | BG8: 2014 | BH8: FEBRUARY
L9: URBAN | N9: 2014 | O9: FEBRUARY | BE9: RURAL+URBAN | BG9: 2015 | BH9: MARCH
L10: RURAL+URBAN | N10: 2015 | O10: MARCH | BG10: 2016 | BH10: APRIL
A11: Brodaer Category | B11: CPI Values | C11: % Contribution | N11: 2016 | O11: APRIL | BG11: 2017 | BH11: MAY
A12: FOOD & NON-ALCHOLIC BEVERAGES | B12: {=INDEX(EXP!AE:AL,MATCH(1,(EXP!A:A=$B$6)*(EXP!B:B=$B$7)*(EXP!C:C=$B$8),0),MATCH($A12,EXP!AE$1:AL$1,0))} -> 2297.3 | C12: =B12/$B$20 -> 0.50162674 | N12: 2017 | O12: MAY | BG12: 2018 | BH12: JUNE
A13: ALCOHOL,TOBACCO & INTOXICANTS | B13: {=INDEX(EXP!AE:AL,MATCH(1,(EXP!A:A=$B$6)*(EXP!B:B=$B$7)*(EXP!C:C=$B$8),0),MATCH($A13,EXP!AE$1:AL$1,0))} -> 196.3 | C13: =B13/$B$20 -> 0.04286307 | N13: 2018 | O13: JUNE | BG13: 2019 | BH13: JULY
A14: CLOTHING AND FOOTWEAR | B14: {=INDEX(EXP!AE:AL,MATCH(1,(EXP!A:A=$B$6)*(EXP!B:B=$B$7)*(EXP!C:C=$B$8),0),MATCH($A14,EXP!AE$1:AL$1,0))} -> 538.2 | C14: =B14/$B$20 -> 0.11751861 | N14: 2019 | O14: JULY | BG14: 2020 | BH14: AUGUST
A15: HOUSING,FUEL AND UTILITIES | B15: {=INDEX(EXP!AE:AL,MATCH(1,(EXP!A:A=$B$6)*(EXP!B:B=$B$7)*(EXP!C:C=$B$8),0),MATCH($A15,EXP!AE$1:AL$1,0))} -> 522.1 | C15: =B15/$B$20 -> 0.1140031 | N15: 2020 | O15: AUGUST | BG15: 2021 | BH15: SEPTEMBER
A16: HEALTHCARE AND EDUCATION | B16: {=INDEX(EXP!AE:AL,MATCH(1,(EXP!A:A=$B$6)*(EXP!B:B=$B$7)*(EXP!C:C=$B$8),0),MATCH($A16,EXP!AE$1:AL$1,0))} -> 524.2 | C16: =B16/$B$20 -> 0.11446165 | N16: 2021 | O16: SEPTEMBER | BG16: 2022 | BH16: OCTOBER
A17: TRANSPORT & COMMUNICATION | B17: {=INDEX(EXP!AE:AL,MATCH(1,(EXP!A:A=$B$6)*(EXP!B:B=$B$7)*(EXP!C:C=$B$8),0),MATCH($A17,EXP!AE$1:AL$1,0))} -> 162.9 | C17: =B17/$B$20 -> 0.035570016 | N17: 2022 | O17: OCTOBER | BG17: 2023 | BH17: NOVEMBER
A18: RECREATION AND CULTURE | B18: {=INDEX(EXP!AE:AL,MATCH(1,(EXP!A:A=$B$6)*(EXP!B:B=$B$7)*(EXP!C:C=$B$8),0),MATCH($A18,EXP!AE$1:AL$1,0))} -> 168.2 | C18: =B18/$B$20 -> 0.036727297 | N18: 2023 | O18: NOVEMBER | BH18: DECEMBER
A19: MISCELLANEOUS | B19: {=INDEX(EXP!AE:AL,MATCH(1,(EXP!A:A=$B$6)*(EXP!B:B=$B$7)*(EXP!C:C=$B$8),0),MATCH($A19,EXP!AE$1:AL$1,0))} -> 170.5 | C19: =B19/$B$20 -> 0.037229513 | O19: DECEMBER
A20: Total | B20: =SUM(B12:B19) -> 4579.7
A34: Recommendation: Food & Non-Alcoholic Beverages is the biggest contributor to CPI inflation. Monitoring food prices along with other high-contribution categories can provide better understanding of overall inflation movement.

Sheet Q2 I
A1: Y-O-Y Inflation Trend Analysis
A5: Sector | B5: Year | C5: Month | D5: General Index | E5: Inflation Rate
A6: Rural+Urban | B6: 2017 | C6: January | D6: {=INDEX(EXP!AD:AD,MATCH(1,(EXP!A:A=$A6)*(EXP!B:B=$B6)*(EXP!C:C=$C6),0))} -> 130.3 | E6: =(D7-D6)/D6 -> 0.05295472
A7: Rural+Urban | B7: 2017 | C7: December | D7: {=INDEX(EXP!AD:AD,MATCH(1,(EXP!A:A=$A7)*(EXP!B:B=$B7)*(EXP!C:C=$C7),0))} -> 137.2
A8: Rural+Urban | B8: 2018 | C8: January | D8: {=INDEX(EXP!AD:AD,MATCH(1,(EXP!A:A=$A8)*(EXP!B:B=$B8)*(EXP!C:C=$C8),0))} -> 136.9 | E8: =(D9-D8)/D8 -> 0.023374726
A9: Rural+Urban | B9: 2018 | C9: December | D9: {=INDEX(EXP!AD:AD,MATCH(1,(EXP!A:A=$A9)*(EXP!B:B=$B9)*(EXP!C:C=$C9),0))} -> 140.1
A10: Rural+Urban | B10: 2019 | C10: January | D10: {=INDEX(EXP!AD:AD,MATCH(1,(EXP!A:A=$A10)*(EXP!B:B=$B10)*(EXP!C:C=$C10),0))} -> 139.6 | E10: =(D11-D10)/D10 -> 0.077363897
A11: Rural+Urban | B11: 2019 | C11: December | D11: {=INDEX(EXP!AD:AD,MATCH(1,(EXP!A:A=$A11)*(EXP!B:B=$B11)*(EXP!C:C=$C11),0))} -> 150.4
A12: Rural+Urban | B12: 2020 | C12: January | D12: {=INDEX(EXP!AD:AD,MATCH(1,(EXP!A:A=$A12)*(EXP!B:B=$B12)*(EXP!C:C=$C12),0))} -> 150.2 | E12: =(D13-D12)/D12 -> 0.05792277
A13: Rural+Urban | B13: 2020 | C13: December | D13: {=INDEX(EXP!AD:AD,MATCH(1,(EXP!A:A=$A13)*(EXP!B:B=$B13)*(EXP!C:C=$C13),0))} -> 158.9
A14: Rural+Urban | B14: 2021 | C14: January | D14: {=INDEX(EXP!AD:AD,MATCH(1,(EXP!A:A=$A14)*(EXP!B:B=$B14)*(EXP!C:C=$C14),0))} -> 157.3 | E14: =(D15-D14)/D14 -> 0.056579784
A15: Rural+Urban | B15: 2021 | C15: December | D15: {=INDEX(EXP!AD:AD,MATCH(1,(EXP!A:A=$A15)*(EXP!B:B=$B15)*(EXP!C:C=$C15),0))} -> 166.2
A16: Rural+Urban | B16: 2022 | C16: January | D16: {=INDEX(EXP!AD:AD,MATCH(1,(EXP!A:A=$A16)*(EXP!B:B=$B16)*(EXP!C:C=$C16),0))} -> 165.7 | E16: =(D17-D16)/D16 -> 0.06035003
A17: Rural+Urban | B17: 2022 | C17: December | D17: {=INDEX(EXP!AD:AD,MATCH(1,(EXP!A:A=$A17)*(EXP!B:B=$B17)*(EXP!C:C=$C17),0))} -> 175.7
A18: Rural+Urban | B18: 2023 | C18: January | D18: {=INDEX(EXP!AD:AD,MATCH(1,(EXP!A:A=$A18)*(EXP!B:B=$B18)*(EXP!C:C=$C18),0))} -> 176.5 | E18: =(D19-D18)/D18 -> 0.014730878
A19: Rural+Urban | B19: 2023 | C19: May | D19: {=INDEX(EXP!AD:AD,MATCH(1,(EXP!A:A=$A19)*(EXP!B:B=$B19)*(EXP!C:C=$C19),0))} -> 179.1
A21: Row Labels | B21: Sum of Inflation Rate
A22: 2017 | B22: 0.05295472
A23: 2018 | B23: 0.023374726
A24: 2019 | B24: 0.077363897
A25: 2020 | B25: 0.05792277
A26: 2021 | B26: 0.056579784
A27: 2022 | B27: 0.06035003
A28: 2023 | B28: 0.014730878
A29: Grand Total | B29: 0.3432768
A31: Recommendation : 2019 recorded the highest inflation rate at 7.74%, while 2023 showed the lowest at 1.47%. Monitoring yearly inflation trends helps identify periods of higher price pressure and stability.

Sheet Q2 II
A1: Category-wise Inflation Analysis and Identification of Major Inflation Drivers
A5: Year | B5: Month | C5: Cereals and products | D5: Meat and fish | E5: Egg | F5: Milk and products | G5: Oils and fats | H5: Fruits | I5: Vegetables | J5: Pulses and products | K5: Sugar and Confectionery | L5: Spices | M5: Non-alcoholic beverages | N5: Prepared meals, snacks, sweets etc. | O5: Food and beverages | P5: Pan, tobacco and intoxicants | Q5: Clothing | R5: Footwear | S5: Clothing and footwear | T5: Housing | U5: Fuel and light | V5: Household goods and services | W5: Health | X5: Transport and communication | Y5: Recreation and amusement | Z5: Education | AA5: Personal care and effects | AB5: Miscellaneous
A6: 2019 | B6: January | C6: 137.1 | D6: 151.4 | E6: 140.2 | F6: 142.1 | G6: 121.8 | H6: 135.4 | I6: 131.3 | J6: 120.3 | K6: 109.1 | L6: 139.4 | M6: 133.3 | N6: 154.6 | O6: 137.4 | P6: 163.2 | Q6: 147.6 | R6: 139 | S6: 146.4 | T6: 147.7 | U6: 139.5 | V6: 143.6 | W6: 145.1 | X6: 123.3 | Y6: 136.7 | Z6: 150.2 | AA6: 132.8 | AB6: 136.9
A7: 2019 | B7: February | C7: 137.6 | D7: 152 | E7: 141.5 | F7: 142.2 | G7: 122 | H7: 136.4 | I7: 129.7 | J7: 121 | K7: 109 | L7: 139.7 | M7: 133.6 | N7: 154.9 | O7: 137.5 | P7: 163.4 | Q7: 147.7 | R7: 139.7 | S7: 146.5 | T7: 148.5 | U7: 138.4 | V7: 143.7 | W7: 145.6 | X7: 123.9 | Y7: 137.1 | Z7: 150.3 | AA7: 134.1 | AB7: 137.4
A8: 2019 | B8: March | C8: 137.8 | D8: 153 | E8: 140.3 | F8: 142.3 | G8: 122 | H8: 137.6 | I8: 132.6 | J8: 121.8 | K8: 109 | L8: 139.5 | M8: 133.7 | N8: 155.2 | O8: 138.1 | P8: 163.5 | Q8: 147.9 | R8: 139.9 | S8: 146.7 | T8: 149 | U8: 139.7 | V8: 143.8 | W8: 146.2 | X8: 124.6 | Y8: 137.7 | Z8: 150.3 | AA8: 133.4 | AB8: 137.7
A9: 2019 | B9: May | C9: 138.3 | D9: 158.5 | E9: 136 | F9: 142.5 | G9: 122 | H9: 146.5 | I9: 143 | J9: 124.9 | K9: 109.9 | L9: 139.9 | M9: 134 | N9: 155.5 | O9: 140.9 | P9: 164.1 | Q9: 148.4 | R9: 140.4 | S9: 147.3 | T9: 150.1 | U9: 140.3 | V9: 143.7 | W9: 146.9 | X9: 124.9 | Y9: 139.2 | Z9: 151.6 | AA9: 133.4 | AB9: 138.2
A10: 2019 | B10: June | C10: 138.7 | D10: 162.1 | E10: 137.8 | F10: 143.3 | G10: 122.2 | H10: 146.8 | I10: 150.5 | J10: 128.3 | K10: 111 | L10: 140.6 | M10: 134.2 | N10: 155.9 | O10: 142.7 | P10: 164.9 | Q10: 148.6 | R10: 140.4 | S10: 147.4 | T10: 149.4 | U10: 141.2 | V10: 143.8 | W10: 147.4 | X10: 124.6 | Y10: 139.6 | Z10: 152.5 | AA10: 134.3 | AB10: 138.6
A11: 2019 | B11: July | C11: 139.3 | D11: 162.7 | E11: 140 | F11: 144 | G11: 122.5 | H11: 150.3 | I11: 160.3 | J11: 130 | K11: 111.1 | L11: 141.7 | M11: 134.7 | N11: 156.2 | O11: 144.7 | P11: 165.2 | Q11: 148.9 | R11: 140.5 | S11: 147.6 | T11: 150.6 | U11: 139.3 | V11: 144.2 | W11: 147.9 | X11: 125.6 | Y11: 140.5 | Z11: 154 | AA11: 135.7 | AB11: 139.5
A12: 2019 | B12: August | C12: 140.1 | D12: 160.6 | E12: 138.5 | F12: 144.7 | G12: 122.9 | H12: 149.4 | I12: 167.4 | J12: 130.9 | K12: 112 | L12: 142.6 | M12: 134.9 | N12: 156.6 | O12: 145.9 | P12: 165.8 | Q12: 149.1 | R12: 140.6 | S12: 147.9 | T12: 151.6 | U12: 138.5 | V12: 144.5 | W12: 148.5 | X12: 125.8 | Y12: 140.9 | Z12: 154.9 | AA12: 138.4 | AB12: 140.2
A13: 2019 | B13: September | C13: 140.9 | D13: 160.8 | E13: 139.6 | F13: 145.4 | G13: 123.5 | H13: 146.6 | I13: 173.2 | J13: 131.6 | K13: 113.2 | L13: 144.1 | M13: 135 | N13: 156.8 | O13: 147 | P13: 166.5 | Q13: 149.2 | R13: 140.6 | S13: 147.9 | T13: 152.2 | U13: 139.2 | V13: 144.6 | W13: 149 | X13: 126.1 | Y13: 141.3 | Z13: 155.2 | AA13: 139.7 | AB13: 140.7
A14: 2019 | B14: October | C14: 141.8 | D14: 161 | E14: 142.6 | F14: 146.2 | G14: 123.9 | H14: 148 | I14: 188.4 | J14: 132.5 | K14: 114 | L14: 145.4 | M14: 135.1 | N14: 157.1 | O14: 149.6 | P14: 167.1 | Q14: 149.4 | R14: 140.8 | S14: 148.2 | T14: 153 | U14: 140.6 | V14: 145 | W14: 149.4 | X14: 126.3 | Y14: 141.7 | Z14: 155.4 | AA14: 140 | AB14: 141
A15: 2019 | B15: November | C15: 142.5 | D15: 163.2 | E15: 145.6 | F15: 146.7 | G15: 124.3 | H15: 147.4 | I15: 199.6 | J15: 135.7 | K15: 114.2 | L15: 147 | M15: 135.3 | N15: 157.5 | O15: 151.9 | P15: 167.9 | Q15: 149.9 | R15: 141 | S15: 148.6 | T15: 153.5 | U15: 142.3 | V15: 145.3 | W15: 149.9 | X15: 126.6 | Y15: 142.1 | Z15: 155.5 | AA15: 140.3 | AB15: 141.3
A16: 2019 | B16: December | C16: 143.5 | D16: 165 | E16: 151.1 | F16: 148.3 | G16: 125.7 | H16: 145.7 | I16: 217 | J16: 138.3 | K16: 114 | L16: 148.7 | M16: 135.8 | N16: 158 | O16: 155 | P16: 168.5 | Q16: 150.3 | R16: 141.3 | S16: 149 | T16: 152.8 | U16: 143.7 | V16: 145.8 | W16: 150.4 | X16: 129.8 | Y16: 142.3 | Z16: 155.7 | AA16: 140.4 | AB16: 142.5
